Workbook

Sheet Strategy
A1: https://wizardofodds.com/video/blackjack-basic-strategy/ | L1: 8 decks
A2: Hard | B2: 2 | C2: 3 | D2: 4 | E2: 5 | F2: 6 | G2: 7 | H2: 8 | I2: 9 | J2: 10 | K2: Ace
A3: 4 | B3: H | C3: H | D3: H | E3: H | F3: H | G3: H | H3: H | I3: H | J3: H | K3: H
A4: 5 | B4: H | C4: H | D4: H | E4: H | F4: H | G4: H | H4: H | I4: H | J4: H | K4: H
A5: 6 | B5: H | C5: H | D5: H | E5: H | F5: H | G5: H | H5: H | I5: H | J5: H | K5: H
A6: 7 | B6: H | C6: H | D6: H | E6: H | F6: H | G6: H | H6: H | I6: H | J6: H | K6: H
A7: 8 | B7: H | C7: H | D7: H | E7: H | F7: H | G7: H | H7: H | I7: H | J7: H | K7: H
A8: 9 | B8: H | C8: D | D8: D | E8: D | F8: D | G8: H | H8: H | I8: H | J8: H | K8: H
A9: 10 | B9: D | C9: D | D9: D | E9: D | F9: D | G9: D | H9: D | I9: D | J9: H | K9: H
A10: 11 | B10: D | C10: D | D10: D | E10: D | F10: D | G10: D | H10: D | I10: D | J10: D | K10: D
A11: 12 | B11: H | C11: H | D11: H | E11: S | F11: H | G11: H | H11: H | I11: H | J11: H | K11: H
A12: 13 | B12: H | C12: S | D12: S | E12: S | F12: S | G12: H | H12: H | I12: H | J12: H | K12: H
A13: 14 | B13: S | C13: S | D13: S | E13: S | F13: S | G13: H | H13: H | I13: H | J13: H | K13: H
A14: 15 | B14: S | C14: S | D14: S | E14: S | F14: S | G14: H | H14: H | I14: H | J14: H | K14: H
... A20: 21 | B20: S | C20: S | D20: S | E20: S | F20: S | G20: S | H20: S | I20: S | J20: S | K20: S
A22: Soft | B22: 2 | C22: 3 | D22: 4 | E22: 5 | F22: 6 | G22: 7 | H22: 8 | I22: 9 | J22: 10 | K22: Ace
A23: 12 | B23: H | C23: H | D23: H | E23: D | F23: D | G23: H | H23: H | I23: H | J23: H | K23: H
A24: 13 | B24: H | C24: H | D24: H | E24: D | F24: D | G24: H | H24: H | I24: H | J24: H | K24: H
A25: 14 | B25: H | C25: H | D25: H | E25: D | F25: D | G25: H | H25: H | I25: H | J25: H | K25: H
A26: 15 | B26: H | C26: H | D26: H | E26: D | F26: D | G26: H | H26: H | I26: H | J26: H | K26: H
A27: 16 | B27: H | C27: H | D27: D | E27: D | F27: D | G27: H | H27: H | I27: H | J27: H | K27: H
A28: 17 | B28: D | C28: D | D28: D | E28: D | F28: D | G28: H | H28: H | I28: H | J28: H | K28: H
A29: 18 | B29: S | C29: DS | D29: DS | E29: DS | F29: DS | G29: S | H29: S | I29: H | J29: H | K29: H
A30: 19 | B30: S | C30: S | D30: S | E30: S | F30: DS | G30: S | H30: S | I30: S | J30: S | K30: S
A31: 20 | B31: S | C31: S | D31: S | E31: S | F31: S | G31: S | H31: S | I31: S | J31: S | K31: S
A32: 21 | B32: S | C32: S | D32: S | E32: S | F32: S | G32: S | H32: S | I32: S | J32: S | K32: S
A34: Pair | B34: 2 | C34: 3 | D34: 4 | E34: 5 | F34: 6 | G34: 7 | H34: 8 | I34: 9 | J34: 10 | K34: Ace
A35: 2 | B35: Y | C35: Y | D35: Y | E35: Y | F35: Y | G35: Y | H35: N | I35: N | J35: N | K35: N
A36: 3 | B36: Y | C36: Y | D36: Y | E36: Y | F36: Y | G36: Y | H36: N | I36: N | J36: N | K36: N
A37: 4 | B37: N | C37: N | D37: N | E37: Y | F37: Y | G37: N | H37: N | I37: N | J37: N | K37: N
A38: 5 | B38: N | C38: N | D38: N | E38: N | F38: N | G38: N | H38: N | I38: N | J38: N | K38: N
A39: 6 | B39: Y | C39: Y | D39: Y | E39: Y | F39: Y | G39: N | H39: N | I39: N | J39: N | K39: N
A40: 7 | B40: Y | C40: Y | D40: Y | E40: Y | F40: Y | G40: Y | H40: N | I40: N | J40: N | K40: N
A41: 8 | B41: Y | C41: Y | D41: Y | E41: Y | F41: Y | G41: Y | H41: Y | I41: Y | J41: Y | K41: Y
A42: 9 | B42: Y | C42: Y | D42: Y | E42: Y | F42: Y | G42: N | H42: Y | I42: Y | J42: N | K42: N
A43: 10 | B43: N | C43: N | D43: N | E43: N | F43: N | G43: N | H43: N | I43: N | J43: N | K43: N
A44: Ace | B44: Y | C44: Y | D44: Y | E44: Y | F44: Y | G44: Y | H44: Y | I44: Y | J44: Y | K44: Y

Sheet Dealer
A1: Outcome | B1: 2 | C1: 3 | D1: 4 | E1: 5 | F1: 6 | G1: 7 | H1: 8 | I1: 9 | J1: 10 | K1: Ace
A2: Bust | B2: =B11 | C2: =C11 | D2: =D11 | E2: =E11 | F2: =F11 | G2: =G11 | H2: =H11 | I2: =I11 | J2: =(SUM(L11:S11)+4*T11)/12 | K2: =(SUM(AG11:AO11)/9)
A3: 17 | B3: =B12 | C3: =C12 | D3: =D12 | E3: =E12 | F3: =F12 | G3: =G12 | H3: =H12 | I3: =I12 | J3: =(SUM(L12:S12)+4*T12)/12 | K3: =(SUM(AG12:AO12)/9)
A4: 18 | B4: =B13 | C4: =C13 | D4: =D13 | E4: =E13 | F4: =F13 | G4: =G13 | H4: =H13 | I4: =I13 | J4: =(SUM(L13:S13)+4*T13)/12 | K4: =(SUM(AG13:AO13)/9)
A5: 19 | B5: =B14 | C5: =C14 | D5: =D14 | E5: =E14 | F5: =F14 | G5: =G14 | H5: =H14 | I5: =I14 | J5: =(SUM(L14:S14)+4*T14)/12 | K5: =(SUM(AG14:AO14)/9)
A6: 20 | B6: =B15 | C6: =C15 | D6: =D15 | E6: =E15 | F6: =F15 | G6: =G15 | H6: =H15 | I6: =I15 | J6: =(SUM(L15:S15)+4*T15)/12 | K6: =(SUM(AG15:AO15)/9)
A7: 21 | B7: =B16 | C7: =C16 | D7: =D16 | E7: =E16 | F7: =F16 | G7: =G16 | H7: =H16 | I7: =I16 | J7: =(SUM(L16:S16)+4*T16)/12 | K7: =(SUM(AG16:AO16)/9)
A8: TOTAL | B8: =SUM(B2:B7) | C8: =SUM(C2:C7) | D8: =SUM(D2:D7) | E8: =SUM(E2:E7) | F8: =SUM(F2:F7) | G8: =SUM(G2:G7) | H8: =SUM(H2:H7) | I8: =SUM(I2:I7) | ... K8: =SUM(K2:K7) | AG8: Soft
A10: Outcome | B10: 2 | C10: 3 | D10: 4 | E10: 5 | F10: 6 | G10: 7 | H10: 8 | I10: 9 | J10: 10 | K10: 11 | L10: 12 | M10: 13 | N10: 14 | O10: 15 | P10: 16 | Q10: 17 | R10: 18 | S10: 19 | T10: 20 | U10: 21 | V10: 22 | W10: 23 | X10: 24 | Y10: 25 | Z10: 26 | AA10: 27 | AB10: 28 | AC10: 29 | AD10: 30 | AE10: 31 | AG10: 12 | AH10: 13 | AI10: 14 | AJ10: 15 | AK10: 16 | AL10: 17 | AM10: 18 | AN10: 19 | AO10: 20 | AP10: 21 | AQ10: 22 | AR10: 23 | AS10: 24 | AT10: 25 | AU10: 26 | AV10: 27 | AW10: 28 | AX10: 29 | AY10: 30 | AZ10: 31
A11: Bust | B11: =(SUM(D11:K11)+4*L11+AH11)/13 | C11: =(SUM(E11:L11)+4*M11+AI11)/13 | D11: =(SUM(F11:M11)+4*N11+AJ11)/13 | E11: =(SUM(G11:N11)+4*O11+AK11)/13 | F11: =(SUM(H11:O11)+4*P11+AL11)/13 | G11: =(SUM(I11:P11)+4*Q11+AM11)/13 | H11: =(SUM(J11:Q11)+4*R11+AN11)/13 | I11: =(SUM(K11:R11)+4*S11+AO11)/13 | ... P11: =(SUM(R11:Y11)+4*Z11+AV11)/13 | V11: 1 | W11: 1 | X11: 1 | Y11: 1 | Z11: 1 | AA11: 1 | AB11: 1 | AC11: 1 | AD11: 1 | AE11: 1 | AG11: =(SUM(AH11:AP11)+4*AQ11)/13 | AH11: =(SUM(AI11:AQ11)+4*AR11)/13 | AI11: =(SUM(AJ11:AR11)+4*AS11)/13 | AJ11: =(SUM(AK11:AS11)+4*AT11)/13 | AK11: =(SUM(AL11:AT11)+4*AU11)/13 | AQ11: =L11 | AR11: =M11 | AS11: =N11 | AT11: =O11 | AU11: =P11 | AV11: =Q11 | AW11: =R11 | AX11: =S11 | ... AZ11: =U11
A12: 17 | B12: =(SUM(D12:K12)+4*L12+AH12)/13 | C12: =(SUM(E12:L12)+4*M12+AI12)/13 | D12: =(SUM(F12:M12)+4*N12+AJ12)/13 | E12: =(SUM(G12:N12)+4*O12+AK12)/13 | F12: =(SUM(H12:O12)+4*P12+AL12)/13 | G12: =(SUM(I12:P12)+4*Q12+AM12)/13 | H12: =(SUM(J12:Q12)+4*R12+AN12)/13 | I12: =(SUM(K12:R12)+4*S12+AO12)/13 | ... P12: =(SUM(R12:Y12)+4*Z12+AV12)/13 | Q12: 1 | AG12: =(SUM(AH12:AP12)+4*AQ12)/13 | AH12: =(SUM(AI12:AQ12)+4*AR12)/13 | AI12: =(SUM(AJ12:AR12)+4*AS12)/13 | AJ12: =(SUM(AK12:AS12)+4*AT12)/13 | AK12: =(SUM(AL12:AT12)+4*AU12)/13 | AL12: 1 | AQ12: =L12 | AR12: =M12 | AS12: =N12 | AT12: =O12 | AU12: =P12 | AV12: =Q12 | AW12: =R12 | AX12: =S12 | ... AZ12: =U12
A13: 18 | B13: =(SUM(D13:K13)+4*L13+AH13)/13 | C13: =(SUM(E13:L13)+4*M13+AI13)/13 | D13: =(SUM(F13:M13)+4*N13+AJ13)/13 | E13: =(SUM(G13:N13)+4*O13+AK13)/13 | F13: =(SUM(H13:O13)+4*P13+AL13)/13 | G13: =(SUM(I13:P13)+4*Q13+AM13)/13 | H13: =(SUM(J13:Q13)+4*R13+AN13)/13 | I13: =(SUM(K13:R13)+4*S13+AO13)/13 | ... P13: =(SUM(R13:Y13)+4*Z13+AV13)/13 | R13: 1 | AG13: =(SUM(AH13:AP13)+4*AQ13)/13 | AH13: =(SUM(AI13:AQ13)+4*AR13)/13 | AI13: =(SUM(AJ13:AR13)+4*AS13)/13 | AJ13: =(SUM(AK13:AS13)+4*AT13)/13 | AK13: =(SUM(AL13:AT13)+4*AU13)/13 | AM13: 1 | AQ13: =L13 | AR13: =M13 | AS13: =N13 | AT13: =O13 | AU13: =P13 | AV13: =Q13 | AW13: =R13 | AX13: =S13 | ... AZ13: =U13
A14: 19 | B14: =(SUM(D14:K14)+4*L14+AH14)/13 | C14: =(SUM(E14:L14)+4*M14+AI14)/13 | D14: =(SUM(F14:M14)+4*N14+AJ14)/13 | E14: =(SUM(G14:N14)+4*O14+AK14)/13 | F14: =(SUM(H14:O14)+4*P14+AL14)/13 | G14: =(SUM(I14:P14)+4*Q14+AM14)/13 | H14: =(SUM(J14:Q14)+4*R14+AN14)/13 | I14: =(SUM(K14:R14)+4*S14+AO14)/13 | ... P14: =(SUM(R14:Y14)+4*Z14+AV14)/13 | S14: 1 | AG14: =(SUM(AH14:AP14)+4*AQ14)/13 | AH14: =(SUM(AI14:AQ14)+4*AR14)/13 | AI14: =(SUM(AJ14:AR14)+4*AS14)/13 | AJ14: =(SUM(AK14:AS14)+4*AT14)/13 | AK14: =(SUM(AL14:AT14)+4*AU14)/13 | AN14: 1 | AQ14: =L14 | AR14: =M14 | AS14: =N14 | AT14: =O14 | AU14: =P14 | AV14: =Q14 | AW14: =R14 | AX14: =S14 | ... AZ14: =U14
A15: 20 | B15: =(SUM(D15:K15)+4*L15+AH15)/13 | C15: =(SUM(E15:L15)+4*M15+AI15)/13 | D15: =(SUM(F15:M15)+4*N15+AJ15)/13 | E15: =(SUM(G15:N15)+4*O15+AK15)/13 | F15: =(SUM(H15:O15)+4*P15+AL15)/13 | G15: =(SUM(I15:P15)+4*Q15+AM15)/13 | H15: =(SUM(J15:Q15)+4*R15+AN15)/13 | I15: =(SUM(K15:R15)+4*S15+AO15)/13 | ... P15: =(SUM(R15:Y15)+4*Z15+AV15)/13 | T15: 1 | AG15: =(SUM(AH15:AP15)+4*AQ15)/13 | AH15: =(SUM(AI15:AQ15)+4*AR15)/13 | AI15: =(SUM(AJ15:AR15)+4*AS15)/13 | AJ15: =(SUM(AK15:AS15)+4*AT15)/13 | AK15: =(SUM(AL15:AT15)+4*AU15)/13 | AO15: 1 | AQ15: =L15 | AR15: =M15 | AS15: =N15 | AT15: =O15 | AU15: =P15 | AV15: =Q15 | AW15: =R15 | AX15: =S15 | ... AZ15: =U15
A16: 21 | B16: =(SUM(D16:K16)+4*L16+AH16)/13 | C16: =(SUM(E16:L16)+4*M16+AI16)/13 | D16: =(SUM(F16:M16)+4*N16+AJ16)/13 | E16: =(SUM(G16:N16)+4*O16+AK16)/13 | F16: =(SUM(H16:O16)+4*P16+AL16)/13 | G16: =(SUM(I16:P16)+4*Q16+AM16)/13 | H16: =(SUM(J16:Q16)+4*R16+AN16)/13 | I16: =(SUM(K16:R16)+4*S16+AO16)/13 | ... P16: =(SUM(R16:Y16)+4*Z16+AV16)/13 | U16: 1 | AG16: =(SUM(AH16:AP16)+4*AQ16)/13 | AH16: =(SUM(AI16:AQ16)+4*AR16)/13 | AI16: =(SUM(AJ16:AR16)+4*AS16)/13 | AJ16: =(SUM(AK16:AS16)+4*AT16)/13 | AK16: =(SUM(AL16:AT16)+4*AU16)/13 | AP16: 1 | AQ16: =L16 | AR16: =M16 | AS16: =N16 | AT16: =O16 | AU16: =P16 | AV16: =Q16 | AW16: =R16 | AX16: =S16 | ... AZ16: =U16
A17: TOTAL | B17: =SUM(B11:B16) | C17: =SUM(C11:C16) | D17: =SUM(D11:D16) | E17: =SUM(E11:E16) | F17: =SUM(F11:F16) | G17: =SUM(G11:G16) | H17: =SUM(H11:H16) | I17: =SUM(I11:I16) | ... AZ17: =SUM(AZ11:AZ16)

Sheet Hit
A1: Hard | B1: 2 | C1: 3 | D1: 4 | E1: 5 | F1: 6 | G1: 7 | H1: 8 | I1: 9 | J1: 10 | K1: Ace
A2: 4 | B2: =(SUM(HS!B4:B11)+4*HS!B12+HS!B35)/13 | C2: =(SUM(HS!C4:C11)+4*HS!C12+HS!C35)/13 | D2: =(SUM(HS!D4:D11)+4*HS!D12+HS!D35)/13 | E2: =(SUM(HS!E4:E11)+4*HS!E12+HS!E35)/13 | F2: =(SUM(HS!F4:F11)+4*HS!F12+HS!F35)/13 | G2: =(SUM(HS!G4:G11)+4*HS!G12+HS!G35)/13 | H2: =(SUM(HS!H4:H11)+4*HS!H12+HS!H35)/13 | I2: =(SUM(HS!I4:I11)+4*HS!I12+HS!I35)/13 | ... K2: =(SUM(HS!K4:K11)+4*HS!K12+HS!K35)/13
A3: 5 | B3: =(SUM(HS!B5:B12)+4*HS!B13+HS!B36)/13 | C3: =(SUM(HS!C5:C12)+4*HS!C13+HS!C36)/13 | D3: =(SUM(HS!D5:D12)+4*HS!D13+HS!D36)/13 | E3: =(SUM(HS!E5:E12)+4*HS!E13+HS!E36)/13 | F3: =(SUM(HS!F5:F12)+4*HS!F13+HS!F36)/13 | G3: =(SUM(HS!G5:G12)+4*HS!G13+HS!G36)/13 | H3: =(SUM(HS!H5:H12)+4*HS!H13+HS!H36)/13 | I3: =(SUM(HS!I5:I12)+4*HS!I13+HS!I36)/13 | ... K3: =(SUM(HS!K5:K12)+4*HS!K13+HS!K36)/13
A4: 6 | B4: =(SUM(HS!B6:B13)+4*HS!B14+HS!B37)/13 | C4: =(SUM(HS!C6:C13)+4*HS!C14+HS!C37)/13 | D4: =(SUM(HS!D6:D13)+4*HS!D14+HS!D37)/13 | E4: =(SUM(HS!E6:E13)+4*HS!E14+HS!E37)/13 | F4: =(SUM(HS!F6:F13)+4*HS!F14+HS!F37)/13 | G4: =(SUM(HS!G6:G13)+4*HS!G14+HS!G37)/13 | H4: =(SUM(HS!H6:H13)+4*HS!H14+HS!H37)/13 | I4: =(SUM(HS!I6:I13)+4*HS!I14+HS!I37)/13 | ... K4: =(SUM(HS!K6:K13)+4*HS!K14+HS!K37)/13
A5: 7 | B5: =(SUM(HS!B7:B14)+4*HS!B15+HS!B38)/13 | C5: =(SUM(HS!C7:C14)+4*HS!C15+HS!C38)/13 | D5: =(SUM(HS!D7:D14)+4*HS!D15+HS!D38)/13 | E5: =(SUM(HS!E7:E14)+4*HS!E15+HS!E38)/13 | F5: =(SUM(HS!F7:F14)+4*HS!F15+HS!F38)/13 | G5: =(SUM(HS!G7:G14)+4*HS!G15+HS!G38)/13 | H5: =(SUM(HS!H7:H14)+4*HS!H15+HS!H38)/13 | I5: =(SUM(HS!I7:I14)+4*HS!I15+HS!I38)/13 | ... K5: =(SUM(HS!K7:K14)+4*HS!K15+HS!K38)/13
A6: 8 | B6: =(SUM(HS!B8:B15)+4*HS!B16+HS!B39)/13 | C6: =(SUM(HS!C8:C15)+4*HS!C16+HS!C39)/13 | D6: =(SUM(HS!D8:D15)+4*HS!D16+HS!D39)/13 | E6: =(SUM(HS!E8:E15)+4*HS!E16+HS!E39)/13 | F6: =(SUM(HS!F8:F15)+4*HS!F16+HS!F39)/13 | G6: =(SUM(HS!G8:G15)+4*HS!G16+HS!G39)/13 | H6: =(SUM(HS!H8:H15)+4*HS!H16+HS!H39)/13 | I6: =(SUM(HS!I8:I15)+4*HS!I16+HS!I39)/13 | ... K6: =(SUM(HS!K8:K15)+4*HS!K16+HS!K39)/13
A7: 9 | B7: =(SUM(HS!B9:B16)+4*HS!B17+HS!B40)/13 | C7: =(SUM(HS!C9:C16)+4*HS!C17+HS!C40)/13 | D7: =(SUM(HS!D9:D16)+4*HS!D17+HS!D40)/13 | E7: =(SUM(HS!E9:E16)+4*HS!E17+HS!E40)/13 | F7: =(SUM(HS!F9:F16)+4*HS!F17+HS!F40)/13 | G7: =(SUM(HS!G9:G16)+4*HS!G17+HS!G40)/13 | H7: =(SUM(HS!H9:H16)+4*HS!H17+HS!H40)/13 | I7: =(SUM(HS!I9:I16)+4*HS!I17+HS!I40)/13 | ... K7: =(SUM(HS!K9:K16)+4*HS!K17+HS!K40)/13
A8: 10 | B8: =(SUM(HS!B10:B17)+4*HS!B18+HS!B41)/13 | C8: =(SUM(HS!C10:C17)+4*HS!C18+HS!C41)/13 | D8: =(SUM(HS!D10:D17)+4*HS!D18+HS!D41)/13 | E8: =(SUM(HS!E10:E17)+4*HS!E18+HS!E41)/13 | F8: =(SUM(HS!F10:F17)+4*HS!F18+HS!F41)/13 | G8: =(SUM(HS!G10:G17)+4*HS!G18+HS!G41)/13 | H8: =(SUM(HS!H10:H17)+4*HS!H18+HS!H41)/13 | I8: =(SUM(HS!I10:I17)+4*HS!I18+HS!I41)/13 | ... K8: =(SUM(HS!K10:K17)+4*HS!K18+HS!K41)/13
A9: 11 | B9: =(SUM(HS!B11:B18)+4*HS!B19+HS!B42)/13 | C9: =(SUM(HS!C11:C18)+4*HS!C19+HS!C42)/13 | D9: =(SUM(HS!D11:D18)+4*HS!D19+HS!D42)/13 | E9: =(SUM(HS!E11:E18)+4*HS!E19+HS!E42)/13 | F9: =(SUM(HS!F11:F18)+4*HS!F19+HS!F42)/13 | G9: =(SUM(HS!G11:G18)+4*HS!G19+HS!G42)/13 | H9: =(SUM(HS!H11:H18)+4*HS!H19+HS!H42)/13 | I9: =(SUM(HS!I11:I18)+4*HS!I19+HS!I42)/13 | ... K9: =(SUM(HS!K11:K18)+4*HS!K19+HS!K42)/13
A10: 12 | B10: =(SUM(HS!B12:B19)+4*HS!B20+HS!B43)/13 | C10: =(SUM(HS!C12:C19)+4*HS!C20+HS!C43)/13 | D10: =(SUM(HS!D12:D19)+4*HS!D20+HS!D43)/13 | E10: =(SUM(HS!E12:E19)+4*HS!E20+HS!E43)/13 | F10: =(SUM(HS!F12:F19)+4*HS!F20+HS!F43)/13 | G10: =(SUM(HS!G12:G19)+4*HS!G20+HS!G43)/13 | H10: =(SUM(HS!H12:H19)+4*HS!H20+HS!H43)/13 | I10: =(SUM(HS!I12:I19)+4*HS!I20+HS!I43)/13 | ... K10: =(SUM(HS!K12:K19)+4*HS!K20+HS!K43)/13
A11: 13 | B11: =(SUM(HS!B13:B20)+4*HS!B21+HS!B44)/13 | C11: =(SUM(HS!C13:C20)+4*HS!C21+HS!C44)/13 | D11: =(SUM(HS!D13:D20)+4*HS!D21+HS!D44)/13 | E11: =(SUM(HS!E13:E20)+4*HS!E21+HS!E44)/13 | F11: =(SUM(HS!F13:F20)+4*HS!F21+HS!F44)/13 | G11: =(SUM(HS!G13:G20)+4*HS!G21+HS!G44)/13 | H11: =(SUM(HS!H13:H20)+4*HS!H21+HS!H44)/13 | I11: =(SUM(HS!I13:I20)+4*HS!I21+HS!I44)/13 | ... K11: =(SUM(HS!K13:K20)+4*HS!K21+HS!K44)/13
A12: 14 | B12: =(SUM(HS!B14:B21)+4*HS!B22+HS!B45)/13 | C12: =(SUM(HS!C14:C21)+4*HS!C22+HS!C45)/13 | D12: =(SUM(HS!D14:D21)+4*HS!D22+HS!D45)/13 | E12: =(SUM(HS!E14:E21)+4*HS!E22+HS!E45)/13 | F12: =(SUM(HS!F14:F21)+4*HS!F22+HS!F45)/13 | G12: =(SUM(HS!G14:G21)+4*HS!G22+HS!G45)/13 | H12: =(SUM(HS!H14:H21)+4*HS!H22+HS!H45)/13 | I12: =(SUM(HS!I14:I21)+4*HS!I22+HS!I45)/13 | ... K12: =(SUM(HS!K14:K21)+4*HS!K22+HS!K45)/13
A13: 15 | B13: =(SUM(HS!B15:B22)+4*HS!B23+HS!B46)/13 | C13: =(SUM(HS!C15:C22)+4*HS!C23+HS!C46)/13 | D13: =(SUM(HS!D15:D22)+4*HS!D23+HS!D46)/13 | E13: =(SUM(HS!E15:E22)+4*HS!E23+HS!E46)/13 | F13: =(SUM(HS!F15:F22)+4*HS!F23+HS!F46)/13 | G13: =(SUM(HS!G15:G22)+4*HS!G23+HS!G46)/13 | H13: =(SUM(HS!H15:H22)+4*HS!H23+HS!H46)/13 | I13: =(SUM(HS!I15:I22)+4*HS!I23+HS!I46)/13 | ... K13: =(SUM(HS!K15:K22)+4*HS!K23+HS!K46)/13
... A18: 20 | B18: =(SUM(HS!B20:B27)+4*HS!B28+HS!B51)/13 | C18: =(SUM(HS!C20:C27)+4*HS!C28+HS!C51)/13 | D18: =(SUM(HS!D20:D27)+4*HS!D28+HS!D51)/13 | E18: =(SUM(HS!E20:E27)+4*HS!E28+HS!E51)/13 | F18: =(SUM(HS!F20:F27)+4*HS!F28+HS!F51)/13 | G18: =(SUM(HS!G20:G27)+4*HS!G28+HS!G51)/13 | H18: =(SUM(HS!H20:H27)+4*HS!H28+HS!H51)/13 | I18: =(SUM(HS!I20:I27)+4*HS!I28+HS!I51)/13 | ... K18: =(SUM(HS!K20:K27)+4*HS!K28+HS!K51)/13
A19: 21 | B19: -1 | C19: -1 | D19: -1 | E19: -1 | F19: -1 | G19: -1 | H19: -1 | I19: -1 | J19: -1 | K19: -1
A20: 22 | B20: -1 | C20: -1 | D20: -1 | E20: -1 | F20: -1 | G20: -1 | H20: -1 | I20: -1 | J20: -1 | K20: -1
A21: 23 | B21: -1 | C21: -1 | D21: -1 | E21: -1 | F21: -1 | G21: -1 | H21: -1 | I21: -1 | J21: -1 | K21: -1
A22: 24 | B22: -1 | C22: -1 | D22: -1 | E22: -1 | F22: -1 | G22: -1 | H22: -1 | I22: -1 | J22: -1 | K22: -1
A23: 25 | B23: -1 | C23: -1 | D23: -1 | E23: -1 | F23: -1 | G23: -1 | H23: -1 | I23: -1 | J23: -1 | K23: -1
A24: 26 | B24: -1 | C24: -1 | D24: -1 | E24: -1 | F24: -1 | G24: -1 | H24: -1 | I24: -1 | J24: -1 | K24: -1
A25: 27 | B25: -1 | C25: -1 | D25: -1 | E25: -1 | F25: -1 | G25: -1 | H25: -1 | I25: -1 | J25: -1 | K25: -1
A26: 28 | B26: -1 | C26: -1 | D26: -1 | E26: -1 | F26: -1 | G26: -1 | H26: -1 | I26: -1 | J26: -1 | K26: -1
A27: 29 | B27: -1 | C27: -1 | D27: -1 | E27: -1 | F27: -1 | G27: -1 | H27: -1 | I27: -1 | J27: -1 | K27: -1
A28: 30 | B28: -1 | C28: -1 | D28: -1 | E28: -1 | F28: -1 | G28: -1 | H28: -1 | I28: -1 | J28: -1 | K28: -1
A29: 31 | B29: -1 | C29: -1 | D29: -1 | E29: -1 | F29: -1 | G29: -1 | H29: -1 | I29: -1 | J29: -1 | K29: -1
A31: Soft
A32: 12 | B32: =(SUM(HS!B33:B41)+4*HS!B42)/13 | C32: =(SUM(HS!C33:C41)+4*HS!C42)/13 | D32: =(SUM(HS!D33:D41)+4*HS!D42)/13 | E32: =(SUM(HS!E33:E41)+4*HS!E42)/13 | F32: =(SUM(HS!F33:F41)+4*HS!F42)/13 | G32: =(SUM(HS!G33:G41)+4*HS!G42)/13 | H32: =(SUM(HS!H33:H41)+4*HS!H42)/13 | I32: =(SUM(HS!I33:I41)+4*HS!I42)/13 | ... K32: =(SUM(HS!K33:K41)+4*HS!K42)/13
A33: 13 | B33: =(SUM(HS!B34:B42)+4*HS!B43)/13 | C33: =(SUM(HS!C34:C42)+4*HS!C43)/13 | D33: =(SUM(HS!D34:D42)+4*HS!D43)/13 | E33: =(SUM(HS!E34:E42)+4*HS!E43)/13 | F33: =(SUM(HS!F34:F42)+4*HS!F43)/13 | G33: =(SUM(HS!G34:G42)+4*HS!G43)/13 | H33: =(SUM(HS!H34:H42)+4*HS!H43)/13 | I33: =(SUM(HS!I34:I42)+4*HS!I43)/13 | ... K33: =(SUM(HS!K34:K42)+4*HS!K43)/13
A34: 14 | B34: =(SUM(HS!B35:B43)+4*HS!B44)/13 | C34: =(SUM(HS!C35:C43)+4*HS!C44)/13 | D34: =(SUM(HS!D35:D43)+4*HS!D44)/13 | E34: =(SUM(HS!E35:E43)+4*HS!E44)/13 | F34: =(SUM(HS!F35:F43)+4*HS!F44)/13 | G34: =(SUM(HS!G35:G43)+4*HS!G44)/13 | H34: =(SUM(HS!H35:H43)+4*HS!H44)/13 | I34: =(SUM(HS!I35:I43)+4*HS!I44)/13 | ... K34: =(SUM(HS!K35:K43)+4*HS!K44)/13
A35: 15 | B35: =(SUM(HS!B36:B44)+4*HS!B45)/13 | C35: =(SUM(HS!C36:C44)+4*HS!C45)/13 | D35: =(SUM(HS!D36:D44)+4*HS!D45)/13 | E35: =(SUM(HS!E36:E44)+4*HS!E45)/13 | F35: =(SUM(HS!F36:F44)+4*HS!F45)/13 | G35: =(SUM(HS!G36:G44)+4*HS!G45)/13 | H35: =(SUM(HS!H36:H44)+4*HS!H45)/13 | I35: =(SUM(HS!I36:I44)+4*HS!I45)/13 | ... K35: =(SUM(HS!K36:K44)+4*HS!K45)/13
A36: 16 | B36: =(SUM(HS!B37:B45)+4*HS!B46)/13 | C36: =(SUM(HS!C37:C45)+4*HS!C46)/13 | D36: =(SUM(HS!D37:D45)+4*HS!D46)/13 | E36: =(SUM(HS!E37:E45)+4*HS!E46)/13 | F36: =(SUM(HS!F37:F45)+4*HS!F46)/13 | G36: =(SUM(HS!G37:G45)+4*HS!G46)/13 | H36: =(SUM(HS!H37:H45)+4*HS!H46)/13 | I36: =(SUM(HS!I37:I45)+4*HS!I46)/13 | ... K36: =(SUM(HS!K37:K45)+4*HS!K46)/13
A37: 17 | B37: =(SUM(HS!B38:B46)+4*HS!B47)/13 | C37: =(SUM(HS!C38:C46)+4*HS!C47)/13 | D37: =(SUM(HS!D38:D46)+4*HS!D47)/13 | E37: =(SUM(HS!E38:E46)+4*HS!E47)/13 | F37: =(SUM(HS!F38:F46)+4*HS!F47)/13 | G37: =(SUM(HS!G38:G46)+4*HS!G47)/13 | H37: =(SUM(HS!H38:H46)+4*HS!H47)/13 | I37: =(SUM(HS!I38:I46)+4*HS!I47)/13 | ... K37: =(SUM(HS!K38:K46)+4*HS!K47)/13
A38: 18 | B38: =(SUM(HS!B39:B47)+4*HS!B48)/13 | C38: =(SUM(HS!C39:C47)+4*HS!C48)/13 | D38: =(SUM(HS!D39:D47)+4*HS!D48)/13 | E38: =(SUM(HS!E39:E47)+4*HS!E48)/13 | F38: =(SUM(HS!F39:F47)+4*HS!F48)/13 | G38: =(SUM(HS!G39:G47)+4*HS!G48)/13 | H38: =(SUM(HS!H39:H47)+4*HS!H48)/13 | I38: =(SUM(HS!I39:I47)+4*HS!I48)/13 | ... K38: =(SUM(HS!K39:K47)+4*HS!K48)/13
A39: 19 | B39: =(SUM(HS!B40:B48)+4*HS!B49)/13 | C39: =(SUM(HS!C40:C48)+4*HS!C49)/13 | D39: =(SUM(HS!D40:D48)+4*HS!D49)/13 | E39: =(SUM(HS!E40:E48)+4*HS!E49)/13 | F39: =(SUM(HS!F40:F48)+4*HS!F49)/13 | G39: =(SUM(HS!G40:G48)+4*HS!G49)/13 | H39: =(SUM(HS!H40:H48)+4*HS!H49)/13 | I39: =(SUM(HS!I40:I48)+4*HS!I49)/13 | ... K39: =(SUM(HS!K40:K48)+4*HS!K49)/13
A40: 20 | B40: =(SUM(HS!B41:B49)+4*HS!B50)/13 | C40: =(SUM(HS!C41:C49)+4*HS!C50)/13 | D40: =(SUM(HS!D41:D49)+4*HS!D50)/13 | E40: =(SUM(HS!E41:E49)+4*HS!E50)/13 | F40: =(SUM(HS!F41:F49)+4*HS!F50)/13 | G40: =(SUM(HS!G41:G49)+4*HS!G50)/13 | H40: =(SUM(HS!H41:H49)+4*HS!H50)/13 | I40: =(SUM(HS!I41:I49)+4*HS!I50)/13 | ... K40: =(SUM(HS!K41:K49)+4*HS!K50)/13
A41: 21 | B41: =(SUM(HS!B42:B50)+4*HS!B51)/13 | C41: =(SUM(HS!C42:C50)+4*HS!C51)/13 | D41: =(SUM(HS!D42:D50)+4*HS!D51)/13 | E41: =(SUM(HS!E42:E50)+4*HS!E51)/13 | F41: =(SUM(HS!F42:F50)+4*HS!F51)/13 | G41: =(SUM(HS!G42:G50)+4*HS!G51)/13 | H41: =(SUM(HS!H42:H50)+4*HS!H51)/13 | I41: =(SUM(HS!I42:I50)+4*HS!I51)/13 | ... K41: =(SUM(HS!K42:K50)+4*HS!K51)/13
A42: 22 | B42: =B10 | C42: =C10 | D42: =D10 | E42: =E10 | F42: =F10 | G42: =G10 | H42: =H10 | I42: =I10 | ... K42: =K10
A43: 23 | B43: =B11 | C43: =C11 | D43: =D11 | E43: =E11 | F43: =F11 | G43: =G11 | H43: =H11 | I43: =I11 | ... K43: =K11
A44: 24 | B44: =B12 | C44: =C12 | D44: =D12 | E44: =E12 | F44: =F12 | G44: =G12 | H44: =H12 | I44: =I12 | ... K44: =K12
A45: 25 | B45: =B13 | C45: =C13 | D45: =D13 | E45: =E13 | F45: =F13 | G45: =G13 | H45: =H13 | I45: =I13 | ... K45: =K13
...

Sheet Stand
A1: Hard | B1: 2 | C1: 3 | D1: 4 | E1: 5 | F1: 6 | G1: 7 | H1: 8 | I1: 9 | J1: 10 | K1: Ace
A2: 4 | B2: =Dealer!B2-SUM(Dealer!B3:B7) | C2: =Dealer!C2-SUM(Dealer!C3:C7) | D2: =Dealer!D2-SUM(Dealer!D3:D7) | E2: =Dealer!E2-SUM(Dealer!E3:E7) | F2: =Dealer!F2-SUM(Dealer!F3:F7) | G2: =Dealer!G2-SUM(Dealer!G3:G7) | H2: =Dealer!H2-SUM(Dealer!H3:H7) | I2: =Dealer!I2-SUM(Dealer!I3:I7) | ... K2: =Dealer!K2-SUM(Dealer!K3:K7)
A3: 5 | B3: =B2 | C3: =C2 | D3: =D2 | E3: =E2 | F3: =F2 | G3: =G2 | H3: =H2 | I3: =I2 | ... K3: =K2
A4: 6 | B4: =B3 | C4: =C3 | D4: =D3 | E4: =E3 | F4: =F3 | G4: =G3 | H4: =H3 | I4: =I3 | ... K4: =K3
A5: 7 | B5: =B4 | C5: =C4 | D5: =D4 | E5: =E4 | F5: =F4 | G5: =G4 | H5: =H4 | I5: =I4 | ... K5: =K4
A6: 8 | B6: =B5 | C6: =C5 | D6: =D5 | E6: =E5 | F6: =F5 | G6: =G5 | H6: =H5 | I6: =I5 | ... K6: =K5
A7: 9 | B7: =B6 | C7: =C6 | D7: =D6 | E7: =E6 | F7: =F6 | G7: =G6 | H7: =H6 | I7: =I6 | ... K7: =K6
A8: 10 | B8: =B7 | C8: =C7 | D8: =D7 | E8: =E7 | F8: =F7 | G8: =G7 | H8: =H7 | I8: =I7 | ... K8: =K7
A9: 11 | B9: =B8 | C9: =C8 | D9: =D8 | E9: =E8 | F9: =F8 | G9: =G8 | H9: =H8 | I9: =I8 | ... K9: =K8
A10: 12 | B10: =B9 | C10: =C9 | D10: =D9 | E10: =E9 | F10: =F9 | G10: =G9 | H10: =H9 | I10: =I9 | ... K10: =K9
A11: 13 | B11: =B10 | C11: =C10 | D11: =D10 | E11: =E10 | F11: =F10 | G11: =G10 | H11: =H10 | I11: =I10 | ... K11: =K10
A12: 14 | B12: =B11 | C12: =C11 | D12: =D11 | E12: =E11 | F12: =F11 | G12: =G11 | H12: =H11 | I12: =I11 | ... K12: =K11
A13: 15 | B13: =B12 | C13: =C12 | D13: =D12 | E13: =E12 | F13: =F12 | G13: =G12 | H13: =H12 | I13: =I12 | ... K13: =K12
A14: 16 | B14: =B13 | C14: =C13 | D14: =D13 | E14: =E13 | F14: =F13 | G14: =G13 | H14: =H13 | I14: =I13 | ... K14: =K13
A15: 17 | B15: =Dealer!B2-SUM(Dealer!B4:B7) | C15: =Dealer!C2-SUM(Dealer!C4:C7) | D15: =Dealer!D2-SUM(Dealer!D4:D7) | E15: =Dealer!E2-SUM(Dealer!E4:E7) | F15: =Dealer!F2-SUM(Dealer!F4:F7) | G15: =Dealer!G2-SUM(Dealer!G4:G7) | H15: =Dealer!H2-SUM(Dealer!H4:H7) | I15: =Dealer!I2-SUM(Dealer!I4:I7) | ... K15: =Dealer!K2-SUM(Dealer!K4:K7)
A16: 18 | B16: =Dealer!B2+Dealer!B3-SUM(Dealer!B5:B7) | C16: =Dealer!C2+Dealer!C3-SUM(Dealer!C5:C7) | D16: =Dealer!D2+Dealer!D3-SUM(Dealer!D5:D7) | E16: =Dealer!E2+Dealer!E3-SUM(Dealer!E5:E7) | F16: =Dealer!F2+Dealer!F3-SUM(Dealer!F5:F7) | G16: =Dealer!G2+Dealer!G3-SUM(Dealer!G5:G7) | H16: =Dealer!H2+Dealer!H3-SUM(Dealer!H5:H7) | I16: =Dealer!I2+Dealer!I3-SUM(Dealer!I5:I7) | ... K16: =Dealer!K2+Dealer!K3-SUM(Dealer!K5:K7)
A17: 19 | B17: =SUM(Dealer!B2:B4)-SUM(Dealer!B6:B7) | C17: =SUM(Dealer!C2:C4)-SUM(Dealer!C6:C7) | D17: =SUM(Dealer!D2:D4)-SUM(Dealer!D6:D7) | E17: =SUM(Dealer!E2:E4)-SUM(Dealer!E6:E7) | F17: =SUM(Dealer!F2:F4)-SUM(Dealer!F6:F7) | G17: =SUM(Dealer!G2:G4)-SUM(Dealer!G6:G7) | H17: =SUM(Dealer!H2:H4)-SUM(Dealer!H6:H7) | I17: =SUM(Dealer!I2:I4)-SUM(Dealer!I6:I7) | ... K17: =SUM(Dealer!K2:K4)-SUM(Dealer!K6:K7)
A18: 20 | B18: =SUM(Dealer!B2:B5)-Dealer!B7 | C18: =SUM(Dealer!C2:C5)-Dealer!C7 | D18: =SUM(Dealer!D2:D5)-Dealer!D7 | E18: =SUM(Dealer!E2:E5)-Dealer!E7 | F18: =SUM(Dealer!F2:F5)-Dealer!F7 | G18: =SUM(Dealer!G2:G5)-Dealer!G7 | H18: =SUM(Dealer!H2:H5)-Dealer!H7 | I18: =SUM(Dealer!I2:I5)-Dealer!I7 | ... K18: =SUM(Dealer!K2:K5)-Dealer!K7
A19: 21 | B19: =SUM(Dealer!B2:B6) | C19: =SUM(Dealer!C2:C6) | D19: =SUM(Dealer!D2:D6) | E19: =SUM(Dealer!E2:E6) | F19: =SUM(Dealer!F2:F6) | G19: =SUM(Dealer!G2:G6) | H19: =SUM(Dealer!H2:H6) | I19: =SUM(Dealer!I2:I6) | ... K19: =SUM(Dealer!K2:K6)
A20: 22 | B20: -1 | C20: -1 | D20: -1 | E20: -1 | F20: -1 | G20: -1 | H20: -1 | I20: -1 | J20: -1 | K20: -1
A21: 23 | B21: -1 | C21: -1 | D21: -1 | E21: -1 | F21: -1 | G21: -1 | H21: -1 | I21: -1 | J21: -1 | K21: -1
A22: 24 | B22: -1 | C22: -1 | D22: -1 | E22: -1 | F22: -1 | G22: -1 | H22: -1 | I22: -1 | J22: -1 | K22: -1
A23: 25 | B23: -1 | C23: -1 | D23: -1 | E23: -1 | F23: -1 | G23: -1 | H23: -1 | I23: -1 | J23: -1 | K23: -1
A24: 26 | B24: -1 | C24: -1 | D24: -1 | E24: -1 | F24: -1 | G24: -1 | H24: -1 | I24: -1 | J24: -1 | K24: -1
A25: 27 | B25: -1 | C25: -1 | D25: -1 | E25: -1 | F25: -1 | G25: -1 | H25: -1 | I25: -1 | J25: -1 | K25: -1
A26: 28 | B26: -1 | C26: -1 | D26: -1 | E26: -1 | F26: -1 | G26: -1 | H26: -1 | I26: -1 | J26: -1 | K26: -1
A27: 29 | B27: -1 | C27: -1 | D27: -1 | E27: -1 | F27: -1 | G27: -1 | H27: -1 | I27: -1 | J27: -1 | K27: -1
A28: 30 | B28: -1 | C28: -1 | D28: -1 | E28: -1 | F28: -1 | G28: -1 | H28: -1 | I28: -1 | J28: -1 | K28: -1
A29: 31 | B29: -1 | C29: -1 | D29: -1 | E29: -1 | F29: -1 | G29: -1 | H29: -1 | I29: -1 | J29: -1 | K29: -1
A31: Soft
A32: 12 | B32: =B10 | C32: =C10 | D32: =D10 | E32: =E10 | F32: =F10 | G32: =G10 | H32: =H10 | I32: =I10 | ... K32: =K10
A33: 13 | B33: =B11 | C33: =C11 | D33: =D11 | E33: =E11 | F33: =F11 | G33: =G11 | H33: =H11 | I33: =I11 | ... K33: =K11
A34: 14 | B34: =B12 | C34: =C12 | D34: =D12 | E34: =E12 | F34: =F12 | G34: =G12 | H34: =H12 | I34: =I12 | ... K34: =K12
A35: 15 | B35: =B13 | C35: =C13 | D35: =D13 | E35: =E13 | F35: =F13 | G35: =G13 | H35: =H13 | I35: =I13 | ... K35: =K13
A36: 16 | B36: =B14 | C36: =C14 | D36: =D14 | E36: =E14 | F36: =F14 | G36: =G14 | H36: =H14 | I36: =I14 | ... K36: =K14
A37: 17 | B37: =B15 | C37: =C15 | D37: =D15 | E37: =E15 | F37: =F15 | G37: =G15 | H37: =H15 | I37: =I15 | ... K37: =K15
A38: 18 | B38: =B16 | C38: =C16 | D38: =D16 | E38: =E16 | F38: =F16 | G38: =G16 | H38: =H16 | I38: =I16 | ... K38: =K16
A39: 19 | B39: =B17 | C39: =C17 | D39: =D17 | E39: =E17 | F39: =F17 | G39: =G17 | H39: =H17 | I39: =I17 | ... K39: =K17
A40: 20 | B40: =B18 | C40: =C18 | D40: =D18 | E40: =E18 | F40: =F18 | G40: =G18 | H40: =H18 | I40: =I18 | ... K40: =K18
A41: 21 | B41: =B19 | C41: =C19 | D41: =D19 | E41: =E19 | F41: =F19 | G41: =G19 | H41: =H19 | I41: =I19 | ... K41: =K19
...

Sheet HS
A1: Hard | B1: 2 | C1: 3 | D1: 4 | E1: 5 | F1: 6 | G1: 7 | H1: 8 | I1: 9 | J1: 10 | K1: Ace | M1: Hard | N1: 2 | O1: 3 | P1: 4 | Q1: 5 | R1: 6 | S1: 7 | T1: 8 | U1: 9 | V1: 10 | W1: Ace
A2: 4 | B2: =MAX(Hit!B2,Stand!B2) | C2: =MAX(Hit!C2,Stand!C2) | D2: =MAX(Hit!D2,Stand!D2) | E2: =MAX(Hit!E2,Stand!E2) | F2: =MAX(Hit!F2,Stand!F2) | G2: =MAX(Hit!G2,Stand!G2) | H2: =MAX(Hit!H2,Stand!H2) | I2: =MAX(Hit!I2,Stand!I2) | ... K2: =MAX(Hit!K2,Stand!K2) | M2: 4 | N2: =IF(B2=Stand!B2,"S","H") | O2: =IF(C2=Stand!C2,"S","H") | P2: =IF(D2=Stand!D2,"S","H") | Q2: =IF(E2=Stand!E2,"S","H") | R2: =IF(F2=Stand!F2,"S","H") | S2: =IF(G2=Stand!G2,"S","H") | T2: =IF(H2=Stand!H2,"S","H") | U2: =IF(I2=Stand!I2,"S","H") | ... W2: =IF(K2=Stand!K2,"S","H")
A3: 5 | B3: =MAX(Hit!B3,Stand!B3) | C3: =MAX(Hit!C3,Stand!C3) | D3: =MAX(Hit!D3,Stand!D3) | E3: =MAX(Hit!E3,Stand!E3) | F3: =MAX(Hit!F3,Stand!F3) | G3: =MAX(Hit!G3,Stand!G3) | H3: =MAX(Hit!H3,Stand!H3) | I3: =MAX(Hit!I3,Stand!I3) | ... K3: =MAX(Hit!K3,Stand!K3) | M3: 5 | N3: =IF(B3=Stand!B3,"S","H") | O3: =IF(C3=Stand!C3,"S","H") | P3: =IF(D3=Stand!D3,"S","H") | Q3: =IF(E3=Stand!E3,"S","H") | R3: =IF(F3=Stand!F3,"S","H") | S3: =IF(G3=Stand!G3,"S","H") | T3: =IF(H3=Stand!H3,"S","H") | U3: =IF(I3=Stand!I3,"S","H") | ... W3: =IF(K3=Stand!K3,"S","H")
A4: 6 | B4: =MAX(Hit!B4,Stand!B4) | C4: =MAX(Hit!C4,Stand!C4) | D4: =MAX(Hit!D4,Stand!D4) | E4: =MAX(Hit!E4,Stand!E4) | F4: =MAX(Hit!F4,Stand!F4) | G4: =MAX(Hit!G4,Stand!G4) | H4: =MAX(Hit!H4,Stand!H4) | I4: =MAX(Hit!I4,Stand!I4) | ... K4: =MAX(Hit!K4,Stand!K4) | M4: 6 | N4: =IF(B4=Stand!B4,"S","H") | O4: =IF(C4=Stand!C4,"S","H") | P4: =IF(D4=Stand!D4,"S","H") | Q4: =IF(E4=Stand!E4,"S","H") | R4: =IF(F4=Stand!F4,"S","H") | S4: =IF(G4=Stand!G4,"S","H") | T4: =IF(H4=Stand!H4,"S","H") | U4: =IF(I4=Stand!I4,"S","H") | ... W4: =IF(K4=Stand!K4,"S","H")
A5: 7 | B5: =MAX(Hit!B5,Stand!B5) | C5: =MAX(Hit!C5,Stand!C5) | D5: =MAX(Hit!D5,Stand!D5) | E5: =MAX(Hit!E5,Stand!E5) | F5: =MAX(Hit!F5,Stand!F5) | G5: =MAX(Hit!G5,Stand!G5) | H5: =MAX(Hit!H5,Stand!H5) | I5: =MAX(Hit!I5,Stand!I5) | ... K5: =MAX(Hit!K5,Stand!K5) | M5: 7 | N5: =IF(B5=Stand!B5,"S","H") | O5: =IF(C5=Stand!C5,"S","H") | P5: =IF(D5=Stand!D5,"S","H") | Q5: =IF(E5=Stand!E5,"S","H") | R5: =IF(F5=Stand!F5,"S","H") | S5: =IF(G5=Stand!G5,"S","H") | T5: =IF(H5=Stand!H5,"S","H") | U5: =IF(I5=Stand!I5,"S","H") | ... W5: =IF(K5=Stand!K5,"S","H")
A6: 8 | B6: =MAX(Hit!B6,Stand!B6) | C6: =MAX(Hit!C6,Stand!C6) | D6: =MAX(Hit!D6,Stand!D6) | E6: =MAX(Hit!E6,Stand!E6) | F6: =MAX(Hit!F6,Stand!F6) | G6: =MAX(Hit!G6,Stand!G6) | H6: =MAX(Hit!H6,Stand!H6) | I6: =MAX(Hit!I6,Stand!I6) | ... K6: =MAX(Hit!K6,Stand!K6) | M6: 8 | N6: =IF(B6=Stand!B6,"S","H") | O6: =IF(C6=Stand!C6,"S","H") | P6: =IF(D6=Stand!D6,"S","H") | Q6: =IF(E6=Stand!E6,"S","H") | R6: =IF(F6=Stand!F6,"S","H") | S6: =IF(G6=Stand!G6,"S","H") | T6: =IF(H6=Stand!H6,"S","H") | U6: =IF(I6=Stand!I6,"S","H") | ... W6: =IF(K6=Stand!K6,"S","H")
A7: 9 | B7: =MAX(Hit!B7,Stand!B7) | C7: =MAX(Hit!C7,Stand!C7) | D7: =MAX(Hit!D7,Stand!D7) | E7: =MAX(Hit!E7,Stand!E7) | F7: =MAX(Hit!F7,Stand!F7) | G7: =MAX(Hit!G7,Stand!G7) | H7: =MAX(Hit!H7,Stand!H7) | I7: =MAX(Hit!I7,Stand!I7) | ... K7: =MAX(Hit!K7,Stand!K7) | M7: 9 | N7: =IF(B7=Stand!B7,"S","H") | O7: =IF(C7=Stand!C7,"S","H") | P7: =IF(D7=Stand!D7,"S","H") | Q7: =IF(E7=Stand!E7,"S","H") | R7: =IF(F7=Stand!F7,"S","H") | S7: =IF(G7=Stand!G7,"S","H") | T7: =IF(H7=Stand!H7,"S","H") | U7: =IF(I7=Stand!I7,"S","H") | ... W7: =IF(K7=Stand!K7,"S","H")
A8: 10 | B8: =MAX(Hit!B8,Stand!B8) | C8: =MAX(Hit!C8,Stand!C8) | D8: =MAX(Hit!D8,Stand!D8) | E8: =MAX(Hit!E8,Stand!E8) | F8: =MAX(Hit!F8,Stand!F8) | G8: =MAX(Hit!G8,Stand!G8) | H8: =MAX(Hit!H8,Stand!H8) | I8: =MAX(Hit!I8,Stand!I8) | ... K8: =MAX(Hit!K8,Stand!K8) | M8: 10 | N8: =IF(B8=Stand!B8,"S","H") | O8: =IF(C8=Stand!C8,"S","H") | P8: =IF(D8=Stand!D8,"S","H") | Q8: =IF(E8=Stand!E8,"S","H") | R8: =IF(F8=Stand!F8,"S","H") | S8: =IF(G8=Stand!G8,"S","H") | T8: =IF(H8=Stand!H8,"S","H") | U8: =IF(I8=Stand!I8,"S","H") | ... W8: =IF(K8=Stand!K8,"S","H")
A9: 11 | B9: =MAX(Hit!B9,Stand!B9) | C9: =MAX(Hit!C9,Stand!C9) | D9: =MAX(Hit!D9,Stand!D9) | E9: =MAX(Hit!E9,Stand!E9) | F9: =MAX(Hit!F9,Stand!F9) | G9: =MAX(Hit!G9,Stand!G9) | H9: =MAX(Hit!H9,Stand!H9) | I9: =MAX(Hit!I9,Stand!I9) | ... K9: =MAX(Hit!K9,Stand!K9) | M9: 11 | N9: =IF(B9=Stand!B9,"S","H") | O9: =IF(C9=Stand!C9,"S","H") | P9: =IF(D9=Stand!D9,"S","H") | Q9: =IF(E9=Stand!E9,"S","H") | R9: =IF(F9=Stand!F9,"S","H") | S9: =IF(G9=Stand!G9,"S","H") | T9: =IF(H9=Stand!H9,"S","H") | U9: =IF(I9=Stand!I9,"S","H") | ... W9: =IF(K9=Stand!K9,"S","H")
A10: 12 | B10: =MAX(Hit!B10,Stand!B10) | C10: =MAX(Hit!C10,Stand!C10) | D10: =MAX(Hit!D10,Stand!D10) | E10: =MAX(Hit!E10,Stand!E10) | F10: =MAX(Hit!F10,Stand!F10) | G10: =MAX(Hit!G10,Stand!G10) | H10: =MAX(Hit!H10,Stand!H10) | I10: =MAX(Hit!I10,Stand!I10) | ... K10: =MAX(Hit!K10,Stand!K10) | M10: 12 | N10: =IF(B10=Stand!B10,"S","H") | O10: =IF(C10=Stand!C10,"S","H") | P10: =IF(D10=Stand!D10,"S","H") | Q10: =IF(E10=Stand!E10,"S","H") | R10: =IF(F10=Stand!F10,"S","H") | S10: =IF(G10=Stand!G10,"S","H") | T10: =IF(H10=Stand!H10,"S","H") | U10: =IF(I10=Stand!I10,"S","H") | ... W10: =IF(K10=Stand!K10,"S","H")
A11: 13 | B11: =MAX(Hit!B11,Stand!B11) | C11: =MAX(Hit!C11,Stand!C11) | D11: =MAX(Hit!D11,Stand!D11) | E11: =MAX(Hit!E11,Stand!E11) | F11: =MAX(Hit!F11,Stand!F11) | G11: =MAX(Hit!G11,Stand!G11) | H11: =MAX(Hit!H11,Stand!H11) | I11: =MAX(Hit!I11,Stand!I11) | ... K11: =MAX(Hit!K11,Stand!K11) | M11: 13 | N11: =IF(B11=Stand!B11,"S","H") | O11: =IF(C11=Stand!C11,"S","H") | P11: =IF(D11=Stand!D11,"S","H") | Q11: =IF(E11=Stand!E11,"S","H") | R11: =IF(F11=Stand!F11,"S","H") | S11: =IF(G11=Stand!G11,"S","H") | T11: =IF(H11=Stand!H11,"S","H") | U11: =IF(I11=Stand!I11,"S","H") | ... W11: =IF(K11=Stand!K11,"S","H")
A12: 14 | B12: =MAX(Hit!B12,Stand!B12) | C12: =MAX(Hit!C12,Stand!C12) | D12: =MAX(Hit!D12,Stand!D12) | E12: =MAX(Hit!E12,Stand!E12) | F12: =MAX(Hit!F12,Stand!F12) | G12: =MAX(Hit!G12,Stand!G12) | H12: =MAX(Hit!H12,Stand!H12) | I12: =MAX(Hit!I12,Stand!I12) | ... K12: =MAX(Hit!K12,Stand!K12) | M12: 14 | N12: =IF(B12=Stand!B12,"S","H") | O12: =IF(C12=Stand!C12,"S","H") | P12: =IF(D12=Stand!D12,"S","H") | Q12: =IF(E12=Stand!E12,"S","H") | R12: =IF(F12=Stand!F12,"S","H") | S12: =IF(G12=Stand!G12,"S","H") | T12: =IF(H12=Stand!H12,"S","H") | U12: =IF(I12=Stand!I12,"S","H") | ... W12: =IF(K12=Stand!K12,"S","H")
A13: 15 | B13: =MAX(Hit!B13,Stand!B13) | C13: =MAX(Hit!C13,Stand!C13) | D13: =MAX(Hit!D13,Stand!D13) | E13: =MAX(Hit!E13,Stand!E13) | F13: =MAX(Hit!F13,Stand!F13) | G13: =MAX(Hit!G13,Stand!G13) | H13: =MAX(Hit!H13,Stand!H13) | I13: =MAX(Hit!I13,Stand!I13) | ... K13: =MAX(Hit!K13,Stand!K13) | M13: 15 | N13: =IF(B13=Stand!B13,"S","H") | O13: =IF(C13=Stand!C13,"S","H") | P13: =IF(D13=Stand!D13,"S","H") | Q13: =IF(E13=Stand!E13,"S","H") | R13: =IF(F13=Stand!F13,"S","H") | S13: =IF(G13=Stand!G13,"S","H") | T13: =IF(H13=Stand!H13,"S","H") | U13: =IF(I13=Stand!I13,"S","H") | ... W13: =IF(K13=Stand!K13,"S","H")
... A19: 21 | B19: =MAX(Hit!B19,Stand!B19) | C19: =MAX(Hit!C19,Stand!C19) | D19: =MAX(Hit!D19,Stand!D19) | E19: =MAX(Hit!E19,Stand!E19) | F19: =MAX(Hit!F19,Stand!F19) | G19: =MAX(Hit!G19,Stand!G19) | H19: =MAX(Hit!H19,Stand!H19) | I19: =MAX(Hit!I19,Stand!I19) | ... K19: =MAX(Hit!K19,Stand!K19) | M19: 21 | N19: =IF(B19=Stand!B19,"S","H") | O19: =IF(C19=Stand!C19,"S","H") | P19: =IF(D19=Stand!D19,"S","H") | Q19: =IF(E19=Stand!E19,"S","H") | R19: =IF(F19=Stand!F19,"S","H") | S19: =IF(G19=Stand!G19,"S","H") | T19: =IF(H19=Stand!H19,"S","H") | U19: =IF(I19=Stand!I19,"S","H") | ... W19: =IF(K19=Stand!K19,"S","H")
A20: 22 | B20: -1 | C20: -1 | D20: -1 | E20: -1 | F20: -1 | G20: -1 | H20: -1 | I20: -1 | J20: -1 | K20: -1
A21: 23 | B21: -1 | C21: -1 | D21: -1 | E21: -1 | F21: -1 | G21: -1 | H21: -1 | I21: -1 | J21: -1 | K21: -1
A22: 24 | B22: -1 | C22: -1 | D22: -1 | E22: -1 | F22: -1 | G22: -1 | H22: -1 | I22: -1 | J22: -1 | K22: -1
A23: 25 | B23: -1 | C23: -1 | D23: -1 | E23: -1 | F23: -1 | G23: -1 | H23: -1 | I23: -1 | J23: -1 | K23: -1
A24: 26 | B24: -1 | C24: -1 | D24: -1 | E24: -1 | F24: -1 | G24: -1 | H24: -1 | I24: -1 | J24: -1 | K24: -1
A25: 27 | B25: -1 | C25: -1 | D25: -1 | E25: -1 | F25: -1 | G25: -1 | H25: -1 | I25: -1 | J25: -1 | K25: -1
A26: 28 | B26: -1 | C26: -1 | D26: -1 | E26: -1 | F26: -1 | G26: -1 | H26: -1 | I26: -1 | J26: -1 | K26: -1
A27: 29 | B27: -1 | C27: -1 | D27: -1 | E27: -1 | F27: -1 | G27: -1 | H27: -1 | I27: -1 | J27: -1 | K27: -1
A28: 30 | B28: -1 | C28: -1 | D28: -1 | E28: -1 | F28: -1 | G28: -1 | H28: -1 | I28: -1 | J28: -1 | K28: -1
A29: 31 | B29: -1 | C29: -1 | D29: -1 | E29: -1 | F29: -1 | G29: -1 | H29: -1 | I29: -1 | J29: -1 | K29: -1
A31: Soft | M31: Soft
A32: 12 | B32: =MAX(Hit!B32,Stand!B32) | C32: =MAX(Hit!C32,Stand!C32) | D32: =MAX(Hit!D32,Stand!D32) | E32: =MAX(Hit!E32,Stand!E32) | F32: =MAX(Hit!F32,Stand!F32) | G32: =MAX(Hit!G32,Stand!G32) | H32: =MAX(Hit!H32,Stand!H32) | I32: =MAX(Hit!I32,Stand!I32) | ... K32: =MAX(Hit!K32,Stand!K32) | M32: 12 | N32: =IF(B32=Stand!B32,"S","H") | O32: =IF(C32=Stand!C32,"S","H") | P32: =IF(D32=Stand!D32,"S","H") | Q32: =IF(E32=Stand!E32,"S","H") | R32: =IF(F32=Stand!F32,"S","H") | S32: =IF(G32=Stand!G32,"S","H") | T32: =IF(H32=Stand!H32,"S","H") | U32: =IF(I32=Stand!I32,"S","H") | ... W32: =IF(K32=Stand!K32,"S","H")
A33: 13 | B33: =MAX(Hit!B33,Stand!B33) | C33: =MAX(Hit!C33,Stand!C33) | D33: =MAX(Hit!D33,Stand!D33) | E33: =MAX(Hit!E33,Stand!E33) | F33: =MAX(Hit!F33,Stand!F33) | G33: =MAX(Hit!G33,Stand!G33) | H33: =MAX(Hit!H33,Stand!H33) | I33: =MAX(Hit!I33,Stand!I33) | ... K33: =MAX(Hit!K33,Stand!K33) | M33: 13 | N33: =IF(B33=Stand!B33,"S","H") | O33: =IF(C33=Stand!C33,"S","H") | P33: =IF(D33=Stand!D33,"S","H") | Q33: =IF(E33=Stand!E33,"S","H") | R33: =IF(F33=Stand!F33,"S","H") | S33: =IF(G33=Stand!G33,"S","H") | T33: =IF(H33=Stand!H33,"S","H") | U33: =IF(I33=Stand!I33,"S","H") | ... W33: =IF(K33=Stand!K33,"S","H")
A34: 14 | B34: =MAX(Hit!B34,Stand!B34) | C34: =MAX(Hit!C34,Stand!C34) | D34: =MAX(Hit!D34,Stand!D34) | E34: =MAX(Hit!E34,Stand!E34) | F34: =MAX(Hit!F34,Stand!F34) | G34: =MAX(Hit!G34,Stand!G34) | H34: =MAX(Hit!H34,Stand!H34) | I34: =MAX(Hit!I34,Stand!I34) | ... K34: =MAX(Hit!K34,Stand!K34) | M34: 14 | N34: =IF(B34=Stand!B34,"S","H") | O34: =IF(C34=Stand!C34,"S","H") | P34: =IF(D34=Stand!D34,"S","H") | Q34: =IF(E34=Stand!E34,"S","H") | R34: =IF(F34=Stand!F34,"S","H") | S34: =IF(G34=Stand!G34,"S","H") | T34: =IF(H34=Stand!H34,"S","H") | U34: =IF(I34=Stand!I34,"S","H") | ... W34: =IF(K34=Stand!K34,"S","H")
A35: 15 | B35: =MAX(Hit!B35,Stand!B35) | C35: =MAX(Hit!C35,Stand!C35) | D35: =MAX(Hit!D35,Stand!D35) | E35: =MAX(Hit!E35,Stand!E35) | F35: =MAX(Hit!F35,Stand!F35) | G35: =MAX(Hit!G35,Stand!G35) | H35: =MAX(Hit!H35,Stand!H35) | I35: =MAX(Hit!I35,Stand!I35) | ... K35: =MAX(Hit!K35,Stand!K35) | M35: 15 | N35: =IF(B35=Stand!B35,"S","H") | O35: =IF(C35=Stand!C35,"S","H") | P35: =IF(D35=Stand!D35,"S","H") | Q35: =IF(E35=Stand!E35,"S","H") | R35: =IF(F35=Stand!F35,"S","H") | S35: =IF(G35=Stand!G35,"S","H") | T35: =IF(H35=Stand!H35,"S","H") | U35: =IF(I35=Stand!I35,"S","H") | ... W35: =IF(K35=Stand!K35,"S","H")
A36: 16 | B36: =MAX(Hit!B36,Stand!B36) | C36: =MAX(Hit!C36,Stand!C36) | D36: =MAX(Hit!D36,Stand!D36) | E36: =MAX(Hit!E36,Stand!E36) | F36: =MAX(Hit!F36,Stand!F36) | G36: =MAX(Hit!G36,Stand!G36) | H36: =MAX(Hit!H36,Stand!H36) | I36: =MAX(Hit!I36,Stand!I36) | ... K36: =MAX(Hit!K36,Stand!K36) | M36: 16 | N36: =IF(B36=Stand!B36,"S","H") | O36: =IF(C36=Stand!C36,"S","H") | P36: =IF(D36=Stand!D36,"S","H") | Q36: =IF(E36=Stand!E36,"S","H") | R36: =IF(F36=Stand!F36,"S","H") | S36: =IF(G36=Stand!G36,"S","H") | T36: =IF(H36=Stand!H36,"S","H") | U36: =IF(I36=Stand!I36,"S","H") | ... W36: =IF(K36=Stand!K36,"S","H")
A37: 17 | B37: =MAX(Hit!B37,Stand!B37) | C37: =MAX(Hit!C37,Stand!C37) | D37: =MAX(Hit!D37,Stand!D37) | E37: =MAX(Hit!E37,Stand!E37) | F37: =MAX(Hit!F37,Stand!F37) | G37: =MAX(Hit!G37,Stand!G37) | H37: =MAX(Hit!H37,Stand!H37) | I37: =MAX(Hit!I37,Stand!I37) | ... K37: =MAX(Hit!K37,Stand!K37) | M37: 17 | N37: =IF(B37=Stand!B37,"S","H") | O37: =IF(C37=Stand!C37,"S","H") | P37: =IF(D37=Stand!D37,"S","H") | Q37: =IF(E37=Stand!E37,"S","H") | R37: =IF(F37=Stand!F37,"S","H") | S37: =IF(G37=Stand!G37,"S","H") | T37: =IF(H37=Stand!H37,"S","H") | U37: =IF(I37=Stand!I37,"S","H") | ... W37: =IF(K37=Stand!K37,"S","H")
A38: 18 | B38: =MAX(Hit!B38,Stand!B38) | C38: =MAX(Hit!C38,Stand!C38) | D38: =MAX(Hit!D38,Stand!D38) | E38: =MAX(Hit!E38,Stand!E38) | F38: =MAX(Hit!F38,Stand!F38) | G38: =MAX(Hit!G38,Stand!G38) | H38: =MAX(Hit!H38,Stand!H38) | I38: =MAX(Hit!I38,Stand!I38) | ... K38: =MAX(Hit!K38,Stand!K38) | M38: 18 | N38: =IF(B38=Stand!B38,"S","H") | O38: =IF(C38=Stand!C38,"S","H") | P38: =IF(D38=Stand!D38,"S","H") | Q38: =IF(E38=Stand!E38,"S","H") | R38: =IF(F38=Stand!F38,"S","H") | S38: =IF(G38=Stand!G38,"S","H") | T38: =IF(H38=Stand!H38,"S","H") | U38: =IF(I38=Stand!I38,"S","H") | ... W38: =IF(K38=Stand!K38,"S","H")
A39: 19 | B39: =MAX(Hit!B39,Stand!B39) | C39: =MAX(Hit!C39,Stand!C39) | D39: =MAX(Hit!D39,Stand!D39) | E39: =MAX(Hit!E39,Stand!E39) | F39: =MAX(Hit!F39,Stand!F39) | G39: =MAX(Hit!G39,Stand!G39) | H39: =MAX(Hit!H39,Stand!H39) | I39: =MAX(Hit!I39,Stand!I39) | ... K39: =MAX(Hit!K39,Stand!K39) | M39: 19 | N39: =IF(B39=Stand!B39,"S","H") | O39: =IF(C39=Stand!C39,"S","H") | P39: =IF(D39=Stand!D39,"S","H") | Q39: =IF(E39=Stand!E39,"S","H") | R39: =IF(F39=Stand!F39,"S","H") | S39: =IF(G39=Stand!G39,"S","H") | T39: =IF(H39=Stand!H39,"S","H") | U39: =IF(I39=Stand!I39,"S","H") | ... W39: =IF(K39=Stand!K39,"S","H")
A40: 20 | B40: =MAX(Hit!B40,Stand!B40) | C40: =MAX(Hit!C40,Stand!C40) | D40: =MAX(Hit!D40,Stand!D40) | E40: =MAX(Hit!E40,Stand!E40) | F40: =MAX(Hit!F40,Stand!F40) | G40: =MAX(Hit!G40,Stand!G40) | H40: =MAX(Hit!H40,Stand!H40) | I40: =MAX(Hit!I40,Stand!I40) | ... K40: =MAX(Hit!K40,Stand!K40) | M40: 20 | N40: =IF(B40=Stand!B40,"S","H") | O40: =IF(C40=Stand!C40,"S","H") | P40: =IF(D40=Stand!D40,"S","H") | Q40: =IF(E40=Stand!E40,"S","H") | R40: =IF(F40=Stand!F40,"S","H") | S40: =IF(G40=Stand!G40,"S","H") | T40: =IF(H40=Stand!H40,"S","H") | U40: =IF(I40=Stand!I40,"S","H") | ... W40: =IF(K40=Stand!K40,"S","H")
A41: 21 | B41: =MAX(Hit!B41,Stand!B41) | C41: =MAX(Hit!C41,Stand!C41) | D41: =MAX(Hit!D41,Stand!D41) | E41: =MAX(Hit!E41,Stand!E41) | F41: =MAX(Hit!F41,Stand!F41) | G41: =MAX(Hit!G41,Stand!G41) | H41: =MAX(Hit!H41,Stand!H41) | I41: =MAX(Hit!I41,Stand!I41) | ... K41: =MAX(Hit!K41,Stand!K41) | M41: 21 | N41: =IF(B41=Stand!B41,"S","H") | O41: =IF(C41=Stand!C41,"S","H") | P41: =IF(D41=Stand!D41,"S","H") | Q41: =IF(E41=Stand!E41,"S","H") | R41: =IF(F41=Stand!F41,"S","H") | S41: =IF(G41=Stand!G41,"S","H") | T41: =IF(H41=Stand!H41,"S","H") | U41: =IF(I41=Stand!I41,"S","H") | ... W41: =IF(K41=Stand!K41,"S","H")
A42: 22 | B42: =MAX(Hit!B42,Stand!B42) | C42: =MAX(Hit!C42,Stand!C42) | D42: =MAX(Hit!D42,Stand!D42) | E42: =MAX(Hit!E42,Stand!E42) | F42: =MAX(Hit!F42,Stand!F42) | G42: =MAX(Hit!G42,Stand!G42) | H42: =MAX(Hit!H42,Stand!H42) | I42: =MAX(Hit!I42,Stand!I42) | ... K42: =MAX(Hit!K42,Stand!K42)
A43: 23 | B43: =MAX(Hit!B43,Stand!B43) | C43: =MAX(Hit!C43,Stand!C43) | D43: =MAX(Hit!D43,Stand!D43) | E43: =MAX(Hit!E43,Stand!E43) | F43: =MAX(Hit!F43,Stand!F43) | G43: =MAX(Hit!G43,Stand!G43) | H43: =MAX(Hit!H43,Stand!H43) | I43: =MAX(Hit!I43,Stand!I43) | ... K43: =MAX(Hit!K43,Stand!K43)
A44: 24 | B44: =MAX(Hit!B44,Stand!B44) | C44: =MAX(Hit!C44,Stand!C44) | D44: =MAX(Hit!D44,Stand!D44) | E44: =MAX(Hit!E44,Stand!E44) | F44: =MAX(Hit!F44,Stand!F44) | G44: =MAX(Hit!G44,Stand!G44) | H44: =MAX(Hit!H44,Stand!H44) | I44: =MAX(Hit!I44,Stand!I44) | ... K44: =MAX(Hit!K44,Stand!K44)
A45: 25 | B45: =MAX(Hit!B45,Stand!B45) | C45: =MAX(Hit!C45,Stand!C45) | D45: =MAX(Hit!D45,Stand!D45) | E45: =MAX(Hit!E45,Stand!E45) | F45: =MAX(Hit!F45,Stand!F45) | G45: =MAX(Hit!G45,Stand!G45) | H45: =MAX(Hit!H45,Stand!H45) | I45: =MAX(Hit!I45,Stand!I45) | ... K45: =MAX(Hit!K45,Stand!K45)
A46: 26 | B46: =MAX(Hit!B46,Stand!B46) | C46: =MAX(Hit!C46,Stand!C46) | D46: =MAX(Hit!D46,Stand!D46) | E46: =MAX(Hit!E46,Stand!E46) | F46: =MAX(Hit!F46,Stand!F46) | G46: =MAX(Hit!G46,Stand!G46) | H46: =MAX(Hit!H46,Stand!H46) | I46: =MAX(Hit!I46,Stand!I46) | ... K46: =MAX(Hit!K46,Stand!K46)
...

Sheet Double
A1: Hard | B1: 2 | C1: 3 | D1: 4 | E1: 5 | F1: 6 | G1: 7 | H1: 8 | I1: 9 | J1: 10 | K1: Ace
A2: 4 | B2: =2*(SUM(Stand!B4:B11)+4*Stand!B12+Stand!B35)/13 | C2: =2*(SUM(Stand!C4:C11)+4*Stand!C12+Stand!C35)/13 | D2: =2*(SUM(Stand!D4:D11)+4*Stand!D12+Stand!D35)/13 | E2: =2*(SUM(Stand!E4:E11)+4*Stand!E12+Stand!E35)/13 | F2: =2*(SUM(Stand!F4:F11)+4*Stand!F12+Stand!F35)/13 | G2: =2*(SUM(Stand!G4:G11)+4*Stand!G12+Stand!G35)/13 | H2: =2*(SUM(Stand!H4:H11)+4*Stand!H12+Stand!H35)/13 | I2: =2*(SUM(Stand!I4:I11)+4*Stand!I12+Stand!I35)/13 | ... K2: =2*(SUM(Stand!K4:K11)+4*Stand!K12+Stand!K35)/13
A3: 5 | B3: =2*(SUM(Stand!B5:B12)+4*Stand!B13+Stand!B36)/13 | C3: =2*(SUM(Stand!C5:C12)+4*Stand!C13+Stand!C36)/13 | D3: =2*(SUM(Stand!D5:D12)+4*Stand!D13+Stand!D36)/13 | E3: =2*(SUM(Stand!E5:E12)+4*Stand!E13+Stand!E36)/13 | F3: =2*(SUM(Stand!F5:F12)+4*Stand!F13+Stand!F36)/13 | G3: =2*(SUM(Stand!G5:G12)+4*Stand!G13+Stand!G36)/13 | H3: =2*(SUM(Stand!H5:H12)+4*Stand!H13+Stand!H36)/13 | I3: =2*(SUM(Stand!I5:I12)+4*Stand!I13+Stand!I36)/13 | ... K3: =2*(SUM(Stand!K5:K12)+4*Stand!K13+Stand!K36)/13
A4: 6 | B4: =2*(SUM(Stand!B6:B13)+4*Stand!B14+Stand!B37)/13 | C4: =2*(SUM(Stand!C6:C13)+4*Stand!C14+Stand!C37)/13 | D4: =2*(SUM(Stand!D6:D13)+4*Stand!D14+Stand!D37)/13 | E4: =2*(SUM(Stand!E6:E13)+4*Stand!E14+Stand!E37)/13 | F4: =2*(SUM(Stand!F6:F13)+4*Stand!F14+Stand!F37)/13 | G4: =2*(SUM(Stand!G6:G13)+4*Stand!G14+Stand!G37)/13 | H4: =2*(SUM(Stand!H6:H13)+4*Stand!H14+Stand!H37)/13 | I4: =2*(SUM(Stand!I6:I13)+4*Stand!I14+Stand!I37)/13 | ... K4: =2*(SUM(Stand!K6:K13)+4*Stand!K14+Stand!K37)/13
A5: 7 | B5: =2*(SUM(Stand!B7:B14)+4*Stand!B15+Stand!B38)/13 | C5: =2*(SUM(Stand!C7:C14)+4*Stand!C15+Stand!C38)/13 | D5: =2*(SUM(Stand!D7:D14)+4*Stand!D15+Stand!D38)/13 | E5: =2*(SUM(Stand!E7:E14)+4*Stand!E15+Stand!E38)/13 | F5: =2*(SUM(Stand!F7:F14)+4*Stand!F15+Stand!F38)/13 | G5: =2*(SUM(Stand!G7:G14)+4*Stand!G15+Stand!G38)/13 | H5: =2*(SUM(Stand!H7:H14)+4*Stand!H15+Stand!H38)/13 | I5: =2*(SUM(Stand!I7:I14)+4*Stand!I15+Stand!I38)/13 | ... K5: =2*(SUM(Stand!K7:K14)+4*Stand!K15+Stand!K38)/13
A6: 8 | B6: =2*(SUM(Stand!B8:B15)+4*Stand!B16+Stand!B39)/13 | C6: =2*(SUM(Stand!C8:C15)+4*Stand!C16+Stand!C39)/13 | D6: =2*(SUM(Stand!D8:D15)+4*Stand!D16+Stand!D39)/13 | E6: =2*(SUM(Stand!E8:E15)+4*Stand!E16+Stand!E39)/13 | F6: =2*(SUM(Stand!F8:F15)+4*Stand!F16+Stand!F39)/13 | G6: =2*(SUM(Stand!G8:G15)+4*Stand!G16+Stand!G39)/13 | H6: =2*(SUM(Stand!H8:H15)+4*Stand!H16+Stand!H39)/13 | I6: =2*(SUM(Stand!I8:I15)+4*Stand!I16+Stand!I39)/13 | ... K6: =2*(SUM(Stand!K8:K15)+4*Stand!K16+Stand!K39)/13
A7: 9 | B7: =2*(SUM(Stand!B9:B16)+4*Stand!B17+Stand!B40)/13 | C7: =2*(SUM(Stand!C9:C16)+4*Stand!C17+Stand!C40)/13 | D7: =2*(SUM(Stand!D9:D16)+4*Stand!D17+Stand!D40)/13 | E7: =2*(SUM(Stand!E9:E16)+4*Stand!E17+Stand!E40)/13 | F7: =2*(SUM(Stand!F9:F16)+4*Stand!F17+Stand!F40)/13 | G7: =2*(SUM(Stand!G9:G16)+4*Stand!G17+Stand!G40)/13 | H7: =2*(SUM(Stand!H9:H16)+4*Stand!H17+Stand!H40)/13 | I7: =2*(SUM(Stand!I9:I16)+4*Stand!I17+Stand!I40)/13 | ... K7: =2*(SUM(Stand!K9:K16)+4*Stand!K17+Stand!K40)/13
A8: 10 | B8: =2*(SUM(Stand!B10:B17)+4*Stand!B18+Stand!B41)/13 | C8: =2*(SUM(Stand!C10:C17)+4*Stand!C18+Stand!C41)/13 | D8: =2*(SUM(Stand!D10:D17)+4*Stand!D18+Stand!D41)/13 | E8: =2*(SUM(Stand!E10:E17)+4*Stand!E18+Stand!E41)/13 | F8: =2*(SUM(Stand!F10:F17)+4*Stand!F18+Stand!F41)/13 | G8: =2*(SUM(Stand!G10:G17)+4*Stand!G18+Stand!G41)/13 | H8: =2*(SUM(Stand!H10:H17)+4*Stand!H18+Stand!H41)/13 | I8: =2*(SUM(Stand!I10:I17)+4*Stand!I18+Stand!I41)/13 | ... K8: =2*(SUM(Stand!K10:K17)+4*Stand!K18+Stand!K41)/13
A9: 11 | B9: =2*(SUM(Stand!B11:B18)+4*Stand!B19+Stand!B42)/13 | C9: =2*(SUM(Stand!C11:C18)+4*Stand!C19+Stand!C42)/13 | D9: =2*(SUM(Stand!D11:D18)+4*Stand!D19+Stand!D42)/13 | E9: =2*(SUM(Stand!E11:E18)+4*Stand!E19+Stand!E42)/13 | F9: =2*(SUM(Stand!F11:F18)+4*Stand!F19+Stand!F42)/13 | G9: =2*(SUM(Stand!G11:G18)+4*Stand!G19+Stand!G42)/13 | H9: =2*(SUM(Stand!H11:H18)+4*Stand!H19+Stand!H42)/13 | I9: =2*(SUM(Stand!I11:I18)+4*Stand!I19+Stand!I42)/13 | ... K9: =2*(SUM(Stand!K11:K18)+4*Stand!K19+Stand!K42)/13
A10: 12 | B10: =2*(SUM(Stand!B11:B19)+4*Stand!B20)/13 | C10: =2*(SUM(Stand!C11:C19)+4*Stand!C20)/13 | D10: =2*(SUM(Stand!D11:D19)+4*Stand!D20)/13 | E10: =2*(SUM(Stand!E11:E19)+4*Stand!E20)/13 | F10: =2*(SUM(Stand!F11:F19)+4*Stand!F20)/13 | G10: =2*(SUM(Stand!G11:G19)+4*Stand!G20)/13 | H10: =2*(SUM(Stand!H11:H19)+4*Stand!H20)/13 | I10: =2*(SUM(Stand!I11:I19)+4*Stand!I20)/13 | ... K10: =2*(SUM(Stand!K11:K19)+4*Stand!K20)/13
A11: 13 | B11: =2*(SUM(Stand!B12:B20)+4*Stand!B21)/13 | C11: =2*(SUM(Stand!C12:C20)+4*Stand!C21)/13 | D11: =2*(SUM(Stand!D12:D20)+4*Stand!D21)/13 | E11: =2*(SUM(Stand!E12:E20)+4*Stand!E21)/13 | F11: =2*(SUM(Stand!F12:F20)+4*Stand!F21)/13 | G11: =2*(SUM(Stand!G12:G20)+4*Stand!G21)/13 | H11: =2*(SUM(Stand!H12:H20)+4*Stand!H21)/13 | I11: =2*(SUM(Stand!I12:I20)+4*Stand!I21)/13 | ... K11: =2*(SUM(Stand!K12:K20)+4*Stand!K21)/13
A12: 14 | B12: =2*(SUM(Stand!B13:B21)+4*Stand!B22)/13 | C12: =2*(SUM(Stand!C13:C21)+4*Stand!C22)/13 | D12: =2*(SUM(Stand!D13:D21)+4*Stand!D22)/13 | E12: =2*(SUM(Stand!E13:E21)+4*Stand!E22)/13 | F12: =2*(SUM(Stand!F13:F21)+4*Stand!F22)/13 | G12: =2*(SUM(Stand!G13:G21)+4*Stand!G22)/13 | H12: =2*(SUM(Stand!H13:H21)+4*Stand!H22)/13 | I12: =2*(SUM(Stand!I13:I21)+4*Stand!I22)/13 | ... K12: =2*(SUM(Stand!K13:K21)+4*Stand!K22)/13
A13: 15 | B13: =2*(SUM(Stand!B14:B22)+4*Stand!B23)/13 | C13: =2*(SUM(Stand!C14:C22)+4*Stand!C23)/13 | D13: =2*(SUM(Stand!D14:D22)+4*Stand!D23)/13 | E13: =2*(SUM(Stand!E14:E22)+4*Stand!E23)/13 | F13: =2*(SUM(Stand!F14:F22)+4*Stand!F23)/13 | G13: =2*(SUM(Stand!G14:G22)+4*Stand!G23)/13 | H13: =2*(SUM(Stand!H14:H22)+4*Stand!H23)/13 | I13: =2*(SUM(Stand!I14:I22)+4*Stand!I23)/13 | ... K13: =2*(SUM(Stand!K14:K22)+4*Stand!K23)/13
A14: 16 | B14: =2*(SUM(Stand!B15:B23)+4*Stand!B24)/13 | C14: =2*(SUM(Stand!C15:C23)+4*Stand!C24)/13 | D14: =2*(SUM(Stand!D15:D23)+4*Stand!D24)/13 | E14: =2*(SUM(Stand!E15:E23)+4*Stand!E24)/13 | F14: =2*(SUM(Stand!F15:F23)+4*Stand!F24)/13 | G14: =2*(SUM(Stand!G15:G23)+4*Stand!G24)/13 | H14: =2*(SUM(Stand!H15:H23)+4*Stand!H24)/13 | I14: =2*(SUM(Stand!I15:I23)+4*Stand!I24)/13 | ... K14: =2*(SUM(Stand!K15:K23)+4*Stand!K24)/13
A15: 17 | B15: =2*(SUM(Stand!B16:B24)+4*Stand!B25)/13 | C15: =2*(SUM(Stand!C16:C24)+4*Stand!C25)/13 | D15: =2*(SUM(Stand!D16:D24)+4*Stand!D25)/13 | E15: =2*(SUM(Stand!E16:E24)+4*Stand!E25)/13 | F15: =2*(SUM(Stand!F16:F24)+4*Stand!F25)/13 | G15: =2*(SUM(Stand!G16:G24)+4*Stand!G25)/13 | H15: =2*(SUM(Stand!H16:H24)+4*Stand!H25)/13 | I15: =2*(SUM(Stand!I16:I24)+4*Stand!I25)/13 | ... K15: =2*(SUM(Stand!K16:K24)+4*Stand!K25)/13
A16: 18 | B16: =2*(SUM(Stand!B17:B25)+4*Stand!B26)/13 | C16: =2*(SUM(Stand!C17:C25)+4*Stand!C26)/13 | D16: =2*(SUM(Stand!D17:D25)+4*Stand!D26)/13 | E16: =2*(SUM(Stand!E17:E25)+4*Stand!E26)/13 | F16: =2*(SUM(Stand!F17:F25)+4*Stand!F26)/13 | G16: =2*(SUM(Stand!G17:G25)+4*Stand!G26)/13 | H16: =2*(SUM(Stand!H17:H25)+4*Stand!H26)/13 | I16: =2*(SUM(Stand!I17:I25)+4*Stand!I26)/13 | ... K16: =2*(SUM(Stand!K17:K25)+4*Stand!K26)/13
A17: 19 | B17: =2*(SUM(Stand!B18:B26)+4*Stand!B27)/13 | C17: =2*(SUM(Stand!C18:C26)+4*Stand!C27)/13 | D17: =2*(SUM(Stand!D18:D26)+4*Stand!D27)/13 | E17: =2*(SUM(Stand!E18:E26)+4*Stand!E27)/13 | F17: =2*(SUM(Stand!F18:F26)+4*Stand!F27)/13 | G17: =2*(SUM(Stand!G18:G26)+4*Stand!G27)/13 | H17: =2*(SUM(Stand!H18:H26)+4*Stand!H27)/13 | I17: =2*(SUM(Stand!I18:I26)+4*Stand!I27)/13 | ... K17: =2*(SUM(Stand!K18:K26)+4*Stand!K27)/13
A18: 20 | B18: =2*(SUM(Stand!B19:B27)+4*Stand!B28)/13 | C18: =2*(SUM(Stand!C19:C27)+4*Stand!C28)/13 | D18: =2*(SUM(Stand!D19:D27)+4*Stand!D28)/13 | E18: =2*(SUM(Stand!E19:E27)+4*Stand!E28)/13 | F18: =2*(SUM(Stand!F19:F27)+4*Stand!F28)/13 | G18: =2*(SUM(Stand!G19:G27)+4*Stand!G28)/13 | H18: =2*(SUM(Stand!H19:H27)+4*Stand!H28)/13 | I18: =2*(SUM(Stand!I19:I27)+4*Stand!I28)/13 | ... K18: =2*(SUM(Stand!K19:K27)+4*Stand!K28)/13
A19: 21 | B19: =2*(SUM(Stand!B20:B28)+4*Stand!B29)/13 | C19: =2*(SUM(Stand!C20:C28)+4*Stand!C29)/13 | D19: =2*(SUM(Stand!D20:D28)+4*Stand!D29)/13 | E19: =2*(SUM(Stand!E20:E28)+4*Stand!E29)/13 | F19: =2*(SUM(Stand!F20:F28)+4*Stand!F29)/13 | G19: =2*(SUM(Stand!G20:G28)+4*Stand!G29)/13 | H19: =2*(SUM(Stand!H20:H28)+4*Stand!H29)/13 | I19: =2*(SUM(Stand!I20:I28)+4*Stand!I29)/13 | ... K19: =2*(SUM(Stand!K20:K28)+4*Stand!K29)/13
A20: 22 | B20: -2 | C20: -2 | D20: -2 | E20: -2 | F20: -2 | G20: -2 | H20: -2 | I20: -2 | J20: -2 | K20: -2
A21: 23 | B21: -2 | C21: -2 | D21: -2 | E21: -2 | F21: -2 | G21: -2 | H21: -2 | I21: -2 | J21: -2 | K21: -2
A22: 24 | B22: -2 | C22: -2 | D22: -2 | E22: -2 | F22: -2 | G22: -2 | H22: -2 | I22: -2 | J22: -2 | K22: -2
A23: 25 | B23: -2 | C23: -2 | D23: -2 | E23: -2 | F23: -2 | G23: -2 | H23: -2 | I23: -2 | J23: -2 | K23: -2
A24: 26 | B24: -2 | C24: -2 | D24: -2 | E24: -2 | F24: -2 | G24: -2 | H24: -2 | I24: -2 | J24: -2 | K24: -2
A25: 27 | B25: -2 | C25: -2 | D25: -2 | E25: -2 | F25: -2 | G25: -2 | H25: -2 | I25: -2 | J25: -2 | K25: -2
A26: 28 | B26: -2 | C26: -2 | D26: -2 | E26: -2 | F26: -2 | G26: -2 | H26: -2 | I26: -2 | J26: -2 | K26: -2
A27: 29 | B27: -2 | C27: -2 | D27: -2 | E27: -2 | F27: -2 | G27: -2 | H27: -2 | I27: -2 | J27: -2 | K27: -2
A28: 30 | B28: -2 | C28: -2 | D28: -2 | E28: -2 | F28: -2 | G28: -2 | H28: -2 | I28: -2 | J28: -2 | K28: -2
A29: 31 | B29: -2 | C29: -2 | D29: -2 | E29: -2 | F29: -2 | G29: -2 | H29: -2 | I29: -2 | J29: -2 | K29: -2
A31: Soft
A32: 12 | B32: =2*(SUM(Stand!B33:B41)+4*Stand!B42)/13 | C32: =2*(SUM(Stand!C33:C41)+4*Stand!C42)/13 | D32: =2*(SUM(Stand!D33:D41)+4*Stand!D42)/13 | E32: =2*(SUM(Stand!E33:E41)+4*Stand!E42)/13 | F32: =2*(SUM(Stand!F33:F41)+4*Stand!F42)/13 | G32: =2*(SUM(Stand!G33:G41)+4*Stand!G42)/13 | H32: =2*(SUM(Stand!H33:H41)+4*Stand!H42)/13 | I32: =2*(SUM(Stand!I33:I41)+4*Stand!I42)/13 | ... K32: =2*(SUM(Stand!K33:K41)+4*Stand!K42)/13
A33: 13 | B33: =2*(SUM(Stand!B34:B42)+4*Stand!B43)/13 | C33: =2*(SUM(Stand!C34:C42)+4*Stand!C43)/13 | D33: =2*(SUM(Stand!D34:D42)+4*Stand!D43)/13 | E33: =2*(SUM(Stand!E34:E42)+4*Stand!E43)/13 | F33: =2*(SUM(Stand!F34:F42)+4*Stand!F43)/13 | G33: =2*(SUM(Stand!G34:G42)+4*Stand!G43)/13 | H33: =2*(SUM(Stand!H34:H42)+4*Stand!H43)/13 | I33: =2*(SUM(Stand!I34:I42)+4*Stand!I43)/13 | ... K33: =2*(SUM(Stand!K34:K42)+4*Stand!K43)/13
A34: 14 | B34: =2*(SUM(Stand!B35:B43)+4*Stand!B44)/13 | C34: =2*(SUM(Stand!C35:C43)+4*Stand!C44)/13 | D34: =2*(SUM(Stand!D35:D43)+4*Stand!D44)/13 | E34: =2*(SUM(Stand!E35:E43)+4*Stand!E44)/13 | F34: =2*(SUM(Stand!F35:F43)+4*Stand!F44)/13 | G34: =2*(SUM(Stand!G35:G43)+4*Stand!G44)/13 | H34: =2*(SUM(Stand!H35:H43)+4*Stand!H44)/13 | I34: =2*(SUM(Stand!I35:I43)+4*Stand!I44)/13 | ... K34: =2*(SUM(Stand!K35:K43)+4*Stand!K44)/13
A35: 15 | B35: =2*(SUM(Stand!B36:B44)+4*Stand!B45)/13 | C35: =2*(SUM(Stand!C36:C44)+4*Stand!C45)/13 | D35: =2*(SUM(Stand!D36:D44)+4*Stand!D45)/13 | E35: =2*(SUM(Stand!E36:E44)+4*Stand!E45)/13 | F35: =2*(SUM(Stand!F36:F44)+4*Stand!F45)/13 | G35: =2*(SUM(Stand!G36:G44)+4*Stand!G45)/13 | H35: =2*(SUM(Stand!H36:H44)+4*Stand!H45)/13 | I35: =2*(SUM(Stand!I36:I44)+4*Stand!I45)/13 | ... K35: =2*(SUM(Stand!K36:K44)+4*Stand!K45)/13
A36: 16 | B36: =2*(SUM(Stand!B37:B45)+4*Stand!B46)/13 | C36: =2*(SUM(Stand!C37:C45)+4*Stand!C46)/13 | D36: =2*(SUM(Stand!D37:D45)+4*Stand!D46)/13 | E36: =2*(SUM(Stand!E37:E45)+4*Stand!E46)/13 | F36: =2*(SUM(Stand!F37:F45)+4*Stand!F46)/13 | G36: =2*(SUM(Stand!G37:G45)+4*Stand!G46)/13 | H36: =2*(SUM(Stand!H37:H45)+4*Stand!H46)/13 | I36: =2*(SUM(Stand!I37:I45)+4*Stand!I46)/13 | ... K36: =2*(SUM(Stand!K37:K45)+4*Stand!K46)/13
A37: 17 | B37: =2*(SUM(Stand!B38:B46)+4*Stand!B47)/13 | C37: =2*(SUM(Stand!C38:C46)+4*Stand!C47)/13 | D37: =2*(SUM(Stand!D38:D46)+4*Stand!D47)/13 | E37: =2*(SUM(Stand!E38:E46)+4*Stand!E47)/13 | F37: =2*(SUM(Stand!F38:F46)+4*Stand!F47)/13 | G37: =2*(SUM(Stand!G38:G46)+4*Stand!G47)/13 | H37: =2*(SUM(Stand!H38:H46)+4*Stand!H47)/13 | I37: =2*(SUM(Stand!I38:I46)+4*Stand!I47)/13 | ... K37: =2*(SUM(Stand!K38:K46)+4*Stand!K47)/13
A38: 18 | B38: =2*(SUM(Stand!B39:B47)+4*Stand!B48)/13 | C38: =2*(SUM(Stand!C39:C47)+4*Stand!C48)/13 | D38: =2*(SUM(Stand!D39:D47)+4*Stand!D48)/13 | E38: =2*(SUM(Stand!E39:E47)+4*Stand!E48)/13 | F38: =2*(SUM(Stand!F39:F47)+4*Stand!F48)/13 | G38: =2*(SUM(Stand!G39:G47)+4*Stand!G48)/13 | H38: =2*(SUM(Stand!H39:H47)+4*Stand!H48)/13 | I38: =2*(SUM(Stand!I39:I47)+4*Stand!I48)/13 | ... K38: =2*(SUM(Stand!K39:K47)+4*Stand!K48)/13
A39: 19 | B39: =2*(SUM(Stand!B40:B48)+4*Stand!B49)/13 | C39: =2*(SUM(Stand!C40:C48)+4*Stand!C49)/13 | D39: =2*(SUM(Stand!D40:D48)+4*Stand!D49)/13 | E39: =2*(SUM(Stand!E40:E48)+4*Stand!E49)/13 | F39: =2*(SUM(Stand!F40:F48)+4*Stand!F49)/13 | G39: =2*(SUM(Stand!G40:G48)+4*Stand!G49)/13 | H39: =2*(SUM(Stand!H40:H48)+4*Stand!H49)/13 | I39: =2*(SUM(Stand!I40:I48)+4*Stand!I49)/13 | ... K39: =2*(SUM(Stand!K40:K48)+4*Stand!K49)/13
A40: 20 | B40: =2*(SUM(Stand!B41:B49)+4*Stand!B50)/13 | C40: =2*(SUM(Stand!C41:C49)+4*Stand!C50)/13 | D40: =2*(SUM(Stand!D41:D49)+4*Stand!D50)/13 | E40: =2*(SUM(Stand!E41:E49)+4*Stand!E50)/13 | F40: =2*(SUM(Stand!F41:F49)+4*Stand!F50)/13 | G40: =2*(SUM(Stand!G41:G49)+4*Stand!G50)/13 | H40: =2*(SUM(Stand!H41:H49)+4*Stand!H50)/13 | I40: =2*(SUM(Stand!I41:I49)+4*Stand!I50)/13 | ... K40: =2*(SUM(Stand!K41:K49)+4*Stand!K50)/13
A41: 21 | B41: =2*(SUM(Stand!B42:B50)+4*Stand!B51)/13 | C41: =2*(SUM(Stand!C42:C50)+4*Stand!C51)/13 | D41: =2*(SUM(Stand!D42:D50)+4*Stand!D51)/13 | E41: =2*(SUM(Stand!E42:E50)+4*Stand!E51)/13 | F41: =2*(SUM(Stand!F42:F50)+4*Stand!F51)/13 | G41: =2*(SUM(Stand!G42:G50)+4*Stand!G51)/13 | H41: =2*(SUM(Stand!H42:H50)+4*Stand!H51)/13 | I41: =2*(SUM(Stand!I42:I50)+4*Stand!I51)/13 | ... K41: =2*(SUM(Stand!K42:K50)+4*Stand!K51)/13
...

Sheet HSD
A1: Hard | B1: 2 | C1: 3 | D1: 4 | E1: 5 | F1: 6 | G1: 7 | H1: 8 | I1: 9 | J1: 10 | K1: Ace | M1: Hard | N1: 2 | O1: 3 | P1: 4 | Q1: 5 | R1: 6 | S1: 7 | T1: 8 | U1: 9 | V1: 10 | W1: Ace
A2: 4 | B2: =MAX(Hit!B2,Stand!B2,Double!B2) | C2: =MAX(Hit!C2,Stand!C2,Double!C2) | D2: =MAX(Hit!D2,Stand!D2,Double!D2) | E2: =MAX(Hit!E2,Stand!E2,Double!E2) | F2: =MAX(Hit!F2,Stand!F2,Double!F2) | G2: =MAX(Hit!G2,Stand!G2,Double!G2) | H2: =MAX(Hit!H2,Stand!H2,Double!H2) | I2: =MAX(Hit!I2,Stand!I2,Double!I2) | ... K2: =MAX(Hit!K2,Stand!K2,Double!K2) | M2: 4 | N2: =IF(B2=Stand!B2,"S",IF(B2=Double!B2,"D","H")) | O2: =IF(C2=Stand!C2,"S",IF(C2=Double!C2,"D","H")) | P2: =IF(D2=Stand!D2,"S",IF(D2=Double!D2,"D","H")) | Q2: =IF(E2=Stand!E2,"S",IF(E2=Double!E2,"D","H")) | R2: =IF(F2=Stand!F2,"S",IF(F2=Double!F2,"D","H")) | S2: =IF(G2=Stand!G2,"S",IF(G2=Double!G2,"D","H")) | T2: =IF(H2=Stand!H2,"S",IF(H2=Double!H2,"D","H")) | U2: =IF(I2=Stand!I2,"S",IF(I2=Double!I2,"D","H")) | ... W2: =IF(K2=Stand!K2,"S",IF(K2=Double!K2,"D","H"))
A3: 5 | B3: =MAX(Hit!B3,Stand!B3,Double!B3) | C3: =MAX(Hit!C3,Stand!C3,Double!C3) | D3: =MAX(Hit!D3,Stand!D3,Double!D3) | E3: =MAX(Hit!E3,Stand!E3,Double!E3) | F3: =MAX(Hit!F3,Stand!F3,Double!F3) | G3: =MAX(Hit!G3,Stand!G3,Double!G3) | H3: =MAX(Hit!H3,Stand!H3,Double!H3) | I3: =MAX(Hit!I3,Stand!I3,Double!I3) | ... K3: =MAX(Hit!K3,Stand!K3,Double!K3) | M3: 5 | N3: =IF(B3=Stand!B3,"S",IF(B3=Double!B3,"D","H")) | O3: =IF(C3=Stand!C3,"S",IF(C3=Double!C3,"D","H")) | P3: =IF(D3=Stand!D3,"S",IF(D3=Double!D3,"D","H")) | Q3: =IF(E3=Stand!E3,"S",IF(E3=Double!E3,"D","H")) | R3: =IF(F3=Stand!F3,"S",IF(F3=Double!F3,"D","H")) | S3: =IF(G3=Stand!G3,"S",IF(G3=Double!G3,"D","H")) | T3: =IF(H3=Stand!H3,"S",IF(H3=Double!H3,"D","H")) | U3: =IF(I3=Stand!I3,"S",IF(I3=Double!I3,"D","H")) | ... W3: =IF(K3=Stand!K3,"S",IF(K3=Double!K3,"D","H"))
A4: 6 | B4: =MAX(Hit!B4,Stand!B4,Double!B4) | C4: =MAX(Hit!C4,Stand!C4,Double!C4) | D4: =MAX(Hit!D4,Stand!D4,Double!D4) | E4: =MAX(Hit!E4,Stand!E4,Double!E4) | F4: =MAX(Hit!F4,Stand!F4,Double!F4) | G4: =MAX(Hit!G4,Stand!G4,Double!G4) | H4: =MAX(Hit!H4,Stand!H4,Double!H4) | I4: =MAX(Hit!I4,Stand!I4,Double!I4) | ... K4: =MAX(Hit!K4,Stand!K4,Double!K4) | M4: 6 | N4: =IF(B4=Stand!B4,"S",IF(B4=Double!B4,"D","H")) | O4: =IF(C4=Stand!C4,"S",IF(C4=Double!C4,"D","H")) | P4: =IF(D4=Stand!D4,"S",IF(D4=Double!D4,"D","H")) | Q4: =IF(E4=Stand!E4,"S",IF(E4=Double!E4,"D","H")) | R4: =IF(F4=Stand!F4,"S",IF(F4=Double!F4,"D","H")) | S4: =IF(G4=Stand!G4,"S",IF(G4=Double!G4,"D","H")) | T4: =IF(H4=Stand!H4,"S",IF(H4=Double!H4,"D","H")) | U4: =IF(I4=Stand!I4,"S",IF(I4=Double!I4,"D","H")) | ... W4: =IF(K4=Stand!K4,"S",IF(K4=Double!K4,"D","H"))
A5: 7 | B5: =MAX(Hit!B5,Stand!B5,Double!B5) | C5: =MAX(Hit!C5,Stand!C5,Double!C5) | D5: =MAX(Hit!D5,Stand!D5,Double!D5) | E5: =MAX(Hit!E5,Stand!E5,Double!E5) | F5: =MAX(Hit!F5,Stand!F5,Double!F5) | G5: =MAX(Hit!G5,Stand!G5,Double!G5) | H5: =MAX(Hit!H5,Stand!H5,Double!H5) | I5: =MAX(Hit!I5,Stand!I5,Double!I5) | ... K5: =MAX(Hit!K5,Stand!K5,Double!K5) | M5: 7 | N5: =IF(B5=Stand!B5,"S",IF(B5=Double!B5,"D","H")) | O5: =IF(C5=Stand!C5,"S",IF(C5=Double!C5,"D","H")) | P5: =IF(D5=Stand!D5,"S",IF(D5=Double!D5,"D","H")) | Q5: =IF(E5=Stand!E5,"S",IF(E5=Double!E5,"D","H")) | R5: =IF(F5=Stand!F5,"S",IF(F5=Double!F5,"D","H")) | S5: =IF(G5=Stand!G5,"S",IF(G5=Double!G5,"D","H")) | T5: =IF(H5=Stand!H5,"S",IF(H5=Double!H5,"D","H")) | U5: =IF(I5=Stand!I5,"S",IF(I5=Double!I5,"D","H")) | ... W5: =IF(K5=Stand!K5,"S",IF(K5=Double!K5,"D","H"))
